Workbook

Sheet 01_Society_Master
A1: Sr. No. | B1: Field | C1: Value | D1: Line 1 | E1: Line 2 | F1: Line 3 | G1: Line 4 | H1: Line 5 | I1: Line 6
A2: 1 | B2: Society Name
A3: 2 | B3: Society Registration No.
A4: 3 | B4: Society Registration Date
A5: 4 | B5: Hedder Address
A6: 5 | B6: Society Address
A7: 6 | B7: Society Email Id
A8: 7 | B8: Society Telephone or Mobile No.
A9: 8 | B9: Total Unit
B10: A) No. of Flat or Room
B11: B) No. Shop
B12: C) No. Office
B13: D) No. Galas
A14: 9 | B14: No. of Print Blank (EXTRA SR. No.)
A15: 10 | B15: Total Unit

Sheet 02_Common_Member_Master
A1: Sr. No. | B1: Membership No. | C1: Share Certificate No. | D1: No. of Shares | E1: Value of One Share | F1: Value of Shares | G1: Share Certificate Range | I1: Members Name Full | O1: Address Permanent | Q1: Address Residential / Care of
G2: From | H2: To | I2: 1 | J2: 2 | K2: 3 | L2: 4 | M2: 5 | N2: 6 | O2: Flat/Room/Shop/Office/Gala No. | P2: Wing No. | Q2: New Address / As Above
A3: 1 | B3: 1 | C3: 1 | D3: 10 (Ten) | E3: 50/- Each | F3: 500/- | G3: 1 | H3: 10 | I3: Nafisha Khatoon Sharif Ahmed Khan | O3: 1/01 | Q3: C.S. No. 364(Pt.), 365(Pt.),366(Pt.), Division Dadar, Naigaon, R. A. Kidwai Marg, Wadala, Mumbai - 400031.
A4: 2 | B4: 2 | C4: 2 | D4: 10 (Ten) | E4: 50/- Each | F4: 500/- | G4: =H3+1 -> 11 | H4: =G4+9 -> 20 | I4: Azhar Husain Mazhar Husain Khan | O4: 1/03 | Q4: C.S. No. 364(Pt.), 365(Pt.),366(Pt.), Division Dadar, Naigaon, R. A. Kidwai Marg, Wadala, Mumbai - 400031.
A5: 3 | B5: 3 | C5: 3 | D5: 10 (Ten) | E5: 50/- Each | F5: 500/- | G5: =H4+1 -> 21 | H5: =G5+9 -> 30 | I5: Abdul Malik Azhar Husain Khan | O5: 1/04 | Q5: C.S. No. 364(Pt.), 365(Pt.),366(Pt.), Division Dadar, Naigaon, R. A. Kidwai Marg, Wadala, Mumbai - 400031.
A6: 4 | B6: 4 | C6: 4 | D6: 10 (Ten) | E6: 50/- Each | F6: 500/- | G6: =H5+1 -> 31 | H6: =G6+9 -> 40 | I6: Abdul Wadood Abdul Mannan Sayyed | O6: 1/09 | Q6: C.S. No. 364(Pt.), 365(Pt.),366(Pt.), Division Dadar, Naigaon, R. A. Kidwai Marg, Wadala, Mumbai - 400031.
A7: 5 | B7: 5 | C7: 5 | D7: 10 (Ten) | E7: 50/- Each | F7: 500/- | G7: =H6+1 -> 41 | H7: =G7+9 -> 50 | I7: Abdulhai Abdul Mannan Sayyed | O7: 1/11 | Q7: C.S. No. 364(Pt.), 365(Pt.),366(Pt.), Division Dadar, Naigaon, R. A. Kidwai Marg, Wadala, Mumbai - 400031.
A8: 6 | B8: 6 | C8: 6 | D8: 10 (Ten) | E8: 50/- Each | F8: 500/- | G8: =H7+1 -> 51 | H8: =G8+9 -> 60 | I8: Shakeel Ahmed Nazir Ahmed Khan | O8: 1/13 | Q8: C.S. No. 364(Pt.), 365(Pt.),366(Pt.), Division Dadar, Naigaon, R. A. Kidwai Marg, Wadala, Mumbai - 400031.
A9: 7 | B9: 7 | C9: 7 | D9: 10 (Ten) | E9: 50/- Each | F9: 500/- | G9: =H8+1 -> 61 | H9: =G9+9 -> 70 | I9: Mohammed Nawaz Ramzan Ali Shaikh | O9: 1/14 | Q9: C.S. No. 364(Pt.), 365(Pt.),366(Pt.), Division Dadar, Naigaon, R. A. Kidwai Marg, Wadala, Mumbai - 400031.
A10: 8 | B10: 8 | C10: 8 | D10: 10 (Ten) | E10: 50/- Each | F10: 500/- | G10: =H9+1 -> 71 | H10: =G10+9 -> 80 | I10: Gulam Husain Kutbullah Khan | O10: 1/15 | Q10: C.S. No. 364(Pt.), 365(Pt.),366(Pt.), Division Dadar, Naigaon, R. A. Kidwai Marg, Wadala, Mumbai - 400031.
A11: 9 | B11: 9 | C11: 9 | D11: 10 (Ten) | E11: 50/- Each | F11: 500/- | G11: =H10+1 -> 81 | H11: =G11+9 -> 90 | I11: Sajid Azhar Husain Khan | O11: 1/16 | Q11: C.S. No. 364(Pt.), 365(Pt.),366(Pt.), Division Dadar, Naigaon, R. A. Kidwai Marg, Wadala, Mumbai - 400031.
A12: 10 | B12: 10 | C12: 10 | D12: 10 (Ten) | E12: 50/- Each | F12: 500/- | G12: =H11+1 -> 91 | H12: =G12+9 -> 100 | I12: Shakilabanoo Mohamed Iqbal Khan | O12: 2/01 | Q12: C.S. No. 364(Pt.), 365(Pt.),366(Pt.), Division Dadar, Naigaon, R. A. Kidwai Marg, Wadala, Mumbai - 400031.
A13: 11 | B13: 11 | C13: 11 | D13: 10 (Ten) | E13: 50/- Each | F13: 500/- | G13: =H12+1 -> 101 | H13: =G13+9 -> 110 | I13: Mohd Hashim Anwarul Haque Khan | O13: 2/02 | Q13: C.S. No. 364(Pt.), 365(Pt.),366(Pt.), Division Dadar, Naigaon, R. A. Kidwai Marg, Wadala, Mumbai - 400031.
A14: 12 | B14: 12 | C14: 12 | D14: 10 (Ten) | E14: 50/- Each | F14: 500/- | G14: =H13+1 -> 111 | H14: =G14+9 -> 120 | I14: Mohammed Shoyab Mohammed Faique Farooque | O14: 2/04 | Q14: C.S. No. 364(Pt.), 365(Pt.),366(Pt.), Division Dadar, Naigaon, R. A. Kidwai Marg, Wadala, Mumbai - 400031.
A15: 13 | B15: 13 | C15: 13 | D15: 10 (Ten) | E15: 50/- Each | F15: 500/- | G15: =H14+1 -> 121 | H15: =G15+9 -> 130 | I15: Ruksana Rashid Ahmed Khan | O15: 2/05 | Q15: C.S. No. 364(Pt.), 365(Pt.),366(Pt.), Division Dadar, Naigaon, R. A. Kidwai Marg, Wadala, Mumbai - 400031.
... A43: 41 | B43: 41 | C43: 41 | D43: 10 (Ten) | E43: 50/- Each | F43: 500/- | G43: =H42+1 -> 401 | H43: =G43+9 -> 410 | I43: Mehboob Azizuddin Khan | O43: 5/03 | Q43: C.S. No. 364(Pt.), 365(Pt.),366(Pt.), Division Dadar, Naigaon, R. A. Kidwai Marg, Wadala, Mumbai - 400031.
A44: 42 | B44: 42 | C44: 42 | D44: 10 (Ten) | E44: 50/- Each | F44: 500/- | G44: =H43+1 -> 411 | H44: =G44+9 -> 420 | I44: Imtiyaz Ali Khan, Afzal Ali Moharram Ali Khan, | J44: Miraz Ali Moharram Ali khan, Abdul Rehman Moharram Ali Khan | K44: Imran Ali Moharram Ali Khan | O44: 5/04 | Q44: C.S. No. 364(Pt.), 365(Pt.),366(Pt.), Division Dadar, Naigaon, R. A. Kidwai Marg, Wadala, Mumbai - 400031.
A45: 43 | B45: 43 | C45: 43 | D45: 10 (Ten) | E45: 50/- Each | F45: 500/- | G45: =H44+1 -> 421 | H45: =G45+9 -> 430 | I45: Sayed Haroon Ali | O45: 5/07 | Q45: C.S. No. 364(Pt.), 365(Pt.),366(Pt.), Division Dadar, Naigaon, R. A. Kidwai Marg, Wadala, Mumbai - 400031.
A46: 44 | B46: 44 | C46: 44 | D46: 10 (Ten) | E46: 50/- Each | F46: 500/- | G46: =H45+1 -> 431 | H46: =G46+9 -> 440 | I46: Ural Pereira & Nirmala Pereira | O46: 5/09 | Q46: C.S. No. 364(Pt.), 365(Pt.),366(Pt.), Division Dadar, Naigaon, R. A. Kidwai Marg, Wadala, Mumbai - 400031.
A47: 45 | B47: 45 | C47: 45 | D47: 10 (Ten) | E47: 50/- Each | F47: 500/- | G47: =H46+1 -> 441 | H47: =G47+9 -> 450 | I47: Alwyn Joseph Stanley Texeira | O47: 5/10 | Q47: C.S. No. 364(Pt.), 365(Pt.),366(Pt.), Division Dadar, Naigaon, R. A. Kidwai Marg, Wadala, Mumbai - 400031.
A48: 46 | B48: 46 | C48: 46 | D48: 10 (Ten) | E48: 50/- Each | F48: 500/- | G48: =H47+1 -> 451 | H48: =G48+9 -> 460 | I48: Riyaz Ahmed Siraj Ahmed Ansari | O48: 5/11 | Q48: C.S. No. 364(Pt.), 365(Pt.),366(Pt.), Division Dadar, Naigaon, R. A. Kidwai Marg, Wadala, Mumbai - 400031.
A49: 47 | B49: 47 | C49: 47 | D49: 10 (Ten) | E49: 50/- Each | F49: 500/- | G49: =H48+1 -> 461 | H49: =G49+9 -> 470 | I49: Adrian Stephen Gomes | O49: 5/14 | Q49: C.S. No. 364(Pt.), 365(Pt.),366(Pt.), Division Dadar, Naigaon, R. A. Kidwai Marg, Wadala, Mumbai - 400031.
A50: 48 | B50: 48 | C50: 48 | D50: 10 (Ten) | E50: 50/- Each | F50: 500/- | G50: =H49+1 -> 471 | H50: =G50+9 -> 480 | I50: Ayeshabi Abdul Rashid Shaikh | O50: 5/16 | Q50: C.S. No. 364(Pt.), 365(Pt.),366(Pt.), Division Dadar, Naigaon, R. A. Kidwai Marg, Wadala, Mumbai - 400031.
A51: 49 | B51: 49 | C51: 49 | D51: 10 (Ten) | E51: 50/- Each | F51: 500/- | G51: =H50+1 -> 481 | H51: =G51+9 -> 490 | I51: Zaibunnissa Naeem Chippa | O51: 6/03 | Q51: C.S. No. 364(Pt.), 365(Pt.),366(Pt.), Division Dadar, Naigaon, R. A. Kidwai Marg, Wadala, Mumbai - 400031.
A52: 50 | B52: 50 | C52: 50 | D52: 10 (Ten) | E52: 50/- Each | F52: 500/- | G52: =H51+1 -> 491 | H52: =G52+9 -> 500 | I52: Naseem Bano Mohammed Rayees Chippa | O52: 6/04 | Q52: C.S. No. 364(Pt.), 365(Pt.),366(Pt.), Division Dadar, Naigaon, R. A. Kidwai Marg, Wadala, Mumbai - 400031.
A53: 51 | B53: 51 | C53: 51 | D53: 10 (Ten) | E53: 50/- Each | F53: 500/- | G53: =H52+1 -> 501 | H53: =G53+9 -> 510 | I53: Fatma Yaqub Shaikh | O53: 6/06 | Q53: C.S. No. 364(Pt.), 365(Pt.),366(Pt.), Division Dadar, Naigaon, R. A. Kidwai Marg, Wadala, Mumbai - 400031.
A54: 52 | B54: 52 | C54: 52 | D54: 10 (Ten) | E54: 50/- Each | F54: 500/- | G54: =H53+1 -> 511 | H54: =G54+9 -> 520 | I54: Rabiya Begum Ishaque Hussain Khan (Late) | O54: 6/07 | Q54: C.S. No. 364(Pt.), 365(Pt.),366(Pt.), Division Dadar, Naigaon, R. A. Kidwai Marg, Wadala, Mumbai - 400031.
A55: 53 | B55: 53 | C55: 53 | D55: 10 (Ten) | E55: 50/- Each | F55: 500/- | G55: =H54+1 -> 521 | H55: =G55+9 -> 530 | I55: Ishaque Hussain Imdad Hussain Khan | O55: 6/08 | Q55: C.S. No. 364(Pt.), 365(Pt.),366(Pt.), Division Dadar, Naigaon, R. A. Kidwai Marg, Wadala, Mumbai - 400031.
A56: 54 | B56: 54 | C56: 54 | D56: 10 (Ten) | E56: 50/- Each | F56: 500/- | G56: =H55+1 -> 531 | H56: =G56+9 -> 540 | I56: Mohammed Jakir Sabir Ali Sayyed | O56: 6/09 | Q56: C.S. No. 364(Pt.), 365(Pt.),366(Pt.), Division Dadar, Naigaon, R. A. Kidwai Marg, Wadala, Mumbai - 400031.
... A65: 63 | B65: 63 | C65: 63 | D65: 10 (Ten) | E65: 50/- Each | F65: 500/- | G65: =H64+1 -> 621 | H65: =G65+9 -> 630 | I65: Jaitunnisa Sirajuddin Khan | O65: 7/04 | Q65: C.S. No. 364(Pt.), 365(Pt.),366(Pt.), Division Dadar, Naigaon, R. A. Kidwai Marg, Wadala, Mumbai - 400031.
A66: 64 | B66: 64 | C66: 64 | D66: 10 (Ten) | E66: 50/- Each | F66: 500/- | G66: =H65+1 -> 631 | H66: =G66+9 -> 640 | I66: Sandip Shantaram Kargutkar | J66: Pradeep Shantaram Kargutkar | O66: 7/06 | Q66: C.S. No. 364(Pt.), 365(Pt.),366(Pt.), Division Dadar, Naigaon, R. A. Kidwai Marg, Wadala, Mumbai - 400031.
A67: 65 | B67: 65 | C67: 65 | D67: 10 (Ten) | E67: 50/- Each | F67: 500/- | G67: =H66+1 -> 641 | H67: =G67+9 -> 650 | I67: Noor Mohammed Habibullah Siddiqui | O67: 7/12 | Q67: C.S. No. 364(Pt.), 365(Pt.),366(Pt.), Division Dadar, Naigaon, R. A. Kidwai Marg, Wadala, Mumbai - 400031.
A68: 66 | B68: 66 | C68: 66 | D68: 10 (Ten) | E68: 50/- Each | F68: 500/- | G68: =H67+1 -> 651 | H68: =G68+9 -> 660 | I68: Abdussalam Kassim Miya Pawaskar | O68: 7/13 | Q68: C.S. No. 364(Pt.), 365(Pt.),366(Pt.), Division Dadar, Naigaon, R. A. Kidwai Marg, Wadala, Mumbai - 400031.
A69: 67 | B69: 67 | C69: 67 | D69: 10 (Ten) | E69: 50/- Each | F69: 500/- | G69: =H68+1 -> 661 | H69: =G69+9 -> 670 | I69: Ganesh Anant Patil | J69: Dinesh Anant Patil | K69: Bharat Anant Patil | O69: 7/14 | Q69: C.S. No. 364(Pt.), 365(Pt.),366(Pt.), Division Dadar, Naigaon, R. A. Kidwai Marg, Wadala, Mumbai - 400031.
A70: 68 | B70: 68 | C70: 68 | D70: 10 (Ten) | E70: 50/- Each | F70: 500/- | G70: =H69+1 -> 671 | H70: =G70+9 -> 680 | I70: Rashid Nawaz Rafiq Ahmed Shaikh | O70: 7/15 | Q70: C.S. No. 364(Pt.), 365(Pt.),366(Pt.), Division Dadar, Naigaon, R. A. Kidwai Marg, Wadala, Mumbai - 400031.
A71: 69 | B71: 69 | C71: 69 | D71: 10 (Ten) | E71: 50/- Each | F71: 500/- | G71: =H70+1 -> 681 | H71: =G71+9 -> 690 | I71: Ashikali Abdulla Khan | O71: 7/16 | Q71: C.S. No. 364(Pt.), 365(Pt.),366(Pt.), Division Dadar, Naigaon, R. A. Kidwai Marg, Wadala, Mumbai - 400031.
A72: 70 | B72: 70 | C72: 70 | D72: 10 (Ten) | E72: 50/- Each | F72: 500/- | G72: =H71+1 -> 691 | H72: =G72+9 -> 700 | I72: Dayaram Gangaprasad Pal | O72: 8/01 | Q72: C.S. No. 364(Pt.), 365(Pt.),366(Pt.), Division Dadar, Naigaon, R. A. Kidwai Marg, Wadala, Mumbai - 400031.
A73: 71 | B73: 71 | C73: 71 | D73: 10 (Ten) | E73: 50/- Each | F73: 500/- | G73: =H72+1 -> 701 | H73: =G73+9 -> 710 | I73: Abdul Hamid Khan | O73: 8/04 | Q73: C.S. No. 364(Pt.), 365(Pt.),366(Pt.), Division Dadar, Naigaon, R. A. Kidwai Marg, Wadala, Mumbai - 400031.
A74: 72 | B74: 72 | C74: 72 | D74: 10 (Ten) | E74: 50/- Each | F74: 500/- | G74: =H73+1 -> 711 | H74: =G74+9 -> 720 | I74: Maimuna khatun Jameel Ahmed Khan | O74: 8/05 | Q74: C.S. No. 364(Pt.), 365(Pt.),366(Pt.), Division Dadar, Naigaon, R. A. Kidwai Marg, Wadala, Mumbai - 400031.
A75: 73 | B75: 73 | C75: 73 | D75: 10 (Ten) | E75: 50/- Each | F75: 500/- | G75: =H74+1 -> 721 | H75: =G75+9 -> 730 | I75: Gulshan Bano Abdul Hafeez Khan | O75: 8/06 | Q75: C.S. No. 364(Pt.), 365(Pt.),366(Pt.), Division Dadar, Naigaon, R. A. Kidwai Marg, Wadala, Mumbai - 400031.
...

Sheet 03_Form_I
A1: Sr. No. | B1: Date of Admission | C1: Date of Payment of Entrance Fees | D1: Members Name Full | J1: Address Permanent | L1: Address Residential / Care of | M1: Occupation | N1: Age on the Date of Admission | O1: Nominee Name Full | U1: Date of Nomination | V1: Date of Cessation of Membership | W1: Reason for Cessation | X1: Remark | Y1: Particulars of Shares Held - Entry 1 | AJ1: Particulars of Shares Held - Entry 2 | AU1: Particulars of Shares Held - Entry 3 | BF1: Particulars of Shares Held - Entry 4 | BQ1: Particulars of Shares Held - Entry 5 | CB1: Particulars of Shares Transferred or Surrendered - Entry 1 | CK1: Particulars of Shares Transferred or Surrendered - Entry 2 | CT1: Particulars of Shares Transferred or Surrendered - Entry 3 | DC1: Particulars of Shares Transferred or Surrendered - Entry 4 | DL1: Particulars of Shares Transferred or Surrendered - Entry 5
D2: 1 | E2: 2 | F2: 3 | G2: 4 | H2: 5 | I2: 6 | J2: Flat/Room/Shop/Office/Gala No. | K2: Wing No. | L2: New Address / As Above | O2: 1 | P2: 2 | Q2: 3 | R2: 4 | S2: 5 | T2: 6 | Y2: Date | Z2: Cash Book Folio No. | AA2: Application | AB2: Allotment | AC2: Amount Received 1st Call | AD2: Amount Received 2nd Call | AE2: Total Amount Received | AF2: No. of Shares Held | AG2: Shares From | AH2: Shares To | AI2: Share Certificate No. | AJ2: Date | AK2: Cash Book Folio No. | AL2: Application | AM2: Allotment | AN2: Amount Received 1st Call | AO2: Amount Received 2nd Call | AP2: Total Amount Received | AQ2: No. of Shares Held | AR2: Shares From | AS2: Shares To | AT2: Share Certificate No. | AU2: Date | AV2: Cash Book Folio No. | AW2: Application | AX2: Allotment | AY2: Amount Received 1st Call | AZ2: Amount Received 2nd Call | BA2: Total Amount Received | BB2: No. of Shares Held | BC2: Shares From | BD2: Shares To | BE2: Share Certificate No. | BF2: Date | BG2: Cash Book Folio No. | BH2: Application | BI2: Allotment | BJ2: Amount Received 1st Call | BK2: Amount Received 2nd Call | BL2: Total Amount Received | BM2: No. of Shares Held | BN2: Shares From | BO2: Shares To | BP2: Share Certificate No. | BQ2: Date | BR2: Cash Book Folio No. | BS2: Application | BT2: Allotment | BU2: Amount Received 1st Call | BV2: Amount Received 2nd Call | BW2: Total Amount Received | BX2: No. of Shares Held | BY2: Shares From | BZ2: Shares To | CA2: Share Certificate No. | CB2: Date | CC2: Cash Book Folio No. | CD2: Transfer Date | CE2: Share Certificate No. Transferred | CF2: No. of Shares Transferred / Refunded | CG2: Balances - No. of Shares Held | CH2: Balances - Serial No. of Share Cert. | CI2: Amount Rs | CJ2: Amount P | CK2: Date | CL2: Cash Book Folio No. | CM2: Transfer Date | CN2: Share Certificate No. Transferred | CO2: No. of Shares Transferred / Refunded | CP2: Balances - No. of Shares Held | CQ2: Balances - Serial No. of Share Cert. | CR2: Amount Rs | CS2: Amount P | CT2: Date | CU2: Cash Book Folio No. | CV2: Transfer Date | CW2: Share Certificate No. Transferred | CX2: No. of Shares Transferred / Refunded | CY2: Balances - No. of Shares Held | CZ2: Balances - Serial No. of Share Cert. | DA2: Amount Rs | DB2: Amount P | DC2: Date | DD2: Cash Book Folio No. | DE2: Transfer Date | DF2: Share Certificate No. Transferred | DG2: No. of Shares Transferred / Refunded | DH2: Balances - No. of Shares Held | DI2: Balances - Serial No. of Share Cert. | DJ2: Amount Rs | DK2: Amount P | DL2: Date | DM2: Cash Book Folio No. | DN2: Transfer Date | DO2: Share Certificate No. Transferred | DP2: No. of Shares Transferred / Refunded | DQ2: Balances - No. of Shares Held | DR2: Balances - Serial No. of Share Cert. | DS2: Amount Rs | DT2: Amount P
A3: =IF('02_Common_Member_Master'!A3="","",'02_Common_Member_Master'!A3) -> 1 | D3: =IF('02_Common_Member_Master'!I3="","",'02_Common_Member_Master'!I3) -> Nafisha Khatoon Sharif Ahmed Khan | E3: =IF('02_Common_Member_Master'!J3="","",'02_Common_Member_Master'!J3) | F3: =IF('02_Common_Member_Master'!K3="","",'02_Common_Member_Master'!K3) | G3: =IF('02_Common_Member_Master'!L3="","",'02_Common_Member_Master'!L3) | H3: =IF('02_Common_Member_Master'!M3="","",'02_Common_Member_Master'!M3) | I3: =IF('02_Common_Member_Master'!N3="","",'02_Common_Member_Master'!N3) | J3: =IF('02_Common_Member_Master'!#REF!="","",'02_Common_Member_Master'!#REF!) -> #REF! | K3: =IF('02_Common_Member_Master'!#REF!="","",'02_Common_Member_Master'!#REF!) -> #REF! | L3: =IF('02_Common_Member_Master'!#REF!="","",'02_Common_Member_Master'!#REF!) -> #REF! | AF3: =IF('02_Common_Member_Master'!D3="","",'02_Common_Member_Master'!D3) -> 10 (Ten) | AG3: =IF('02_Common_Member_Master'!G3="","",'02_Common_Member_Master'!G3) -> 1 | AH3: =IF('02_Common_Member_Master'!H3="","",'02_Common_Member_Master'!H3) -> 10 | AI3: =IF('02_Common_Member_Master'!C3="","",'02_Common_Member_Master'!C3) -> 1
A4: =IF('02_Common_Member_Master'!A4="","",'02_Common_Member_Master'!A4) -> 2 | D4: =IF('02_Common_Member_Master'!I4="","",'02_Common_Member_Master'!I4) -> Azhar Husain Mazhar Husain Khan | E4: =IF('02_Common_Member_Master'!J4="","",'02_Common_Member_Master'!J4) | F4: =IF('02_Common_Member_Master'!K4="","",'02_Common_Member_Master'!K4) | G4: =IF('02_Common_Member_Master'!L4="","",'02_Common_Member_Master'!L4) | H4: =IF('02_Common_Member_Master'!M4="","",'02_Common_Member_Master'!M4) | I4: =IF('02_Common_Member_Master'!N4="","",'02_Common_Member_Master'!N4) | J4: ` | K4: =IF('02_Common_Member_Master'!#REF!="","",'02_Common_Member_Master'!#REF!) -> #REF! | L4: =IF('02_Common_Member_Master'!#REF!="","",'02_Common_Member_Master'!#REF!) -> #REF! | AF4: =IF('02_Common_Member_Master'!D4="","",'02_Common_Member_Master'!D4) -> 10 (Ten) | AG4: =IF('02_Common_Member_Master'!G4="","",'02_Common_Member_Master'!G4) -> 11 | AH4: =IF('02_Common_Member_Master'!H4="","",'02_Common_Member_Master'!H4) -> 20 | AI4: =IF('02_Common_Member_Master'!C4="","",'02_Common_Member_Master'!C4) -> 2
A5: =IF('02_Common_Member_Master'!A5="","",'02_Common_Member_Master'!A5) -> 3 | D5: =IF('02_Common_Member_Master'!I5="","",'02_Common_Member_Master'!I5) -> Abdul Malik Azhar Husain Khan | E5: =IF('02_Common_Member_Master'!J5="","",'02_Common_Member_Master'!J5) | F5: =IF('02_Common_Member_Master'!K5="","",'02_Common_Member_Master'!K5) | G5: =IF('02_Common_Member_Master'!L5="","",'02_Common_Member_Master'!L5) | H5: =IF('02_Common_Member_Master'!M5="","",'02_Common_Member_Master'!M5) | I5: =IF('02_Common_Member_Master'!N5="","",'02_Common_Member_Master'!N5) | J5: =IF('02_Common_Member_Master'!#REF!="","",'02_Common_Member_Master'!#REF!) -> #REF! | K5: =IF('02_Common_Member_Master'!#REF!="","",'02_Common_Member_Master'!#REF!) -> #REF! | L5: =IF('02_Common_Member_Master'!#REF!="","",'02_Common_Member_Master'!#REF!) -> #REF! | AF5: =IF('02_Common_Member_Master'!D5="","",'02_Common_Member_Master'!D5) -> 10 (Ten) | AG5: =IF('02_Common_Member_Master'!G5="","",'02_Common_Member_Master'!G5) -> 21 | AH5: =IF('02_Common_Member_Master'!H5="","",'02_Common_Member_Master'!H5) -> 30 | AI5: =IF('02_Common_Member_Master'!C5="","",'02_Common_Member_Master'!C5) -> 3
A6: =IF('02_Common_Member_Master'!A6="","",'02_Common_Member_Master'!A6) -> 4 | D6: =IF('02_Common_Member_Master'!I6="","",'02_Common_Member_Master'!I6) -> Abdul Wadood Abdul Mannan Sayyed | E6: =IF('02_Common_Member_Master'!J6="","",'02_Common_Member_Master'!J6) | F6: =IF('02_Common_Member_Master'!K6="","",'02_Common_Member_Master'!K6) | G6: =IF('02_Common_Member_Master'!L6="","",'02_Common_Member_Master'!L6) | H6: =IF('02_Common_Member_Master'!M6="","",'02_Common_Member_Master'!M6) | I6: =IF('02_Common_Member_Master'!N6="","",'02_Common_Member_Master'!N6) | J6: =IF('02_Common_Member_Master'!#REF!="","",'02_Common_Member_Master'!#REF!) -> #REF! | K6: =IF('02_Common_Member_Master'!#REF!="","",'02_Common_Member_Master'!#REF!) -> #REF! | L6: =IF('02_Common_Member_Master'!#REF!="","",'02_Common_Member_Master'!#REF!) -> #REF! | AF6: =IF('02_Common_Member_Master'!D6="","",'02_Common_Member_Master'!D6) -> 10 (Ten) | AG6: =IF('02_Common_Member_Master'!G6="","",'02_Common_Member_Master'!G6) -> 31 | AH6: =IF('02_Common_Member_Master'!H6="","",'02_Common_Member_Master'!H6) -> 40 | AI6: =IF('02_Common_Member_Master'!C6="","",'02_Common_Member_Master'!C6) -> 4
A7: =IF('02_Common_Member_Master'!A7="","",'02_Common_Member_Master'!A7) -> 5 | D7: =IF('02_Common_Member_Master'!I7="","",'02_Common_Member_Master'!I7) -> Abdulhai Abdul Mannan Sayyed | E7: =IF('02_Common_Member_Master'!J7="","",'02_Common_Member_Master'!J7) | F7: =IF('02_Common_Member_Master'!K7="","",'02_Common_Member_Master'!K7) | G7: =IF('02_Common_Member_Master'!L7="","",'02_Common_Member_Master'!L7) | H7: =IF('02_Common_Member_Master'!M7="","",'02_Common_Member_Master'!M7) | I7: =IF('02_Common_Member_Master'!N7="","",'02_Common_Member_Master'!N7) | J7: =IF('02_Common_Member_Master'!#REF!="","",'02_Common_Member_Master'!#REF!) -> #REF! | K7: =IF('02_Common_Member_Master'!#REF!="","",'02_Common_Member_Master'!#REF!) -> #REF! | L7: =IF('02_Common_Member_Master'!#REF!="","",'02_Common_Member_Master'!#REF!) -> #REF! | AF7: =IF('02_Common_Member_Master'!D7="","",'02_Common_Member_Master'!D7) -> 10 (Ten) | AG7: =IF('02_Common_Member_Master'!G7="","",'02_Common_Member_Master'!G7) -> 41 | AH7: =IF('02_Common_Member_Master'!H7="","",'02_Common_Member_Master'!H7) -> 50 | AI7: =IF('02_Common_Member_Master'!C7="","",'02_Common_Member_Master'!C7) -> 5
A8: =IF('02_Common_Member_Master'!A8="","",'02_Common_Member_Master'!A8) -> 6 | D8: =IF('02_Common_Member_Master'!I8="","",'02_Common_Member_Master'!I8) -> Shakeel Ahmed Nazir Ahmed Khan | E8: =IF('02_Common_Member_Master'!J8="","",'02_Common_Member_Master'!J8) | F8: =IF('02_Common_Member_Master'!K8="","",'02_Common_Member_Master'!K8) | G8: =IF('02_Common_Member_Master'!L8="","",'02_Common_Member_Master'!L8) | H8: =IF('02_Common_Member_Master'!M8="","",'02_Common_Member_Master'!M8) | I8: =IF('02_Common_Member_Master'!N8="","",'02_Common_Member_Master'!N8) | J8: =IF('02_Common_Member_Master'!#REF!="","",'02_Common_Member_Master'!#REF!) -> #REF! | K8: =IF('02_Common_Member_Master'!#REF!="","",'02_Common_Member_Master'!#REF!) -> #REF! | L8: =IF('02_Common_Member_Master'!#REF!="","",'02_Common_Member_Master'!#REF!) -> #REF! | AF8: =IF('02_Common_Member_Master'!D8="","",'02_Common_Member_Master'!D8) -> 10 (Ten) | AG8: =IF('02_Common_Member_Master'!G8="","",'02_Common_Member_Master'!G8) -> 51 | AH8: =IF('02_Common_Member_Master'!H8="","",'02_Common_Member_Master'!H8) -> 60 | AI8: =IF('02_Common_Member_Master'!C8="","",'02_Common_Member_Master'!C8) -> 6
A9: =IF('02_Common_Member_Master'!A9="","",'02_Common_Member_Master'!A9) -> 7 | D9: =IF('02_Common_Member_Master'!I9="","",'02_Common_Member_Master'!I9) -> Mohammed Nawaz Ramzan Ali Shaikh | E9: =IF('02_Common_Member_Master'!J9="","",'02_Common_Member_Master'!J9) | F9: =IF('02_Common_Member_Master'!K9="","",'02_Common_Member_Master'!K9) | G9: =IF('02_Common_Member_Master'!L9="","",'02_Common_Member_Master'!L9) | H9: =IF('02_Common_Member_Master'!M9="","",'02_Common_Member_Master'!M9) | I9: =IF('02_Common_Member_Master'!N9="","",'02_Common_Member_Master'!N9) | J9: =IF('02_Common_Member_Master'!#REF!="","",'02_Common_Member_Master'!#REF!) -> #REF! | K9: =IF('02_Common_Member_Master'!#REF!="","",'02_Common_Member_Master'!#REF!) -> #REF! | L9: =IF('02_Common_Member_Master'!#REF!="","",'02_Common_Member_Master'!#REF!) -> #REF! | AF9: =IF('02_Common_Member_Master'!D9="","",'02_Common_Member_Master'!D9) -> 10 (Ten) | AG9: =IF('02_Common_Member_Master'!G9="","",'02_Common_Member_Master'!G9) -> 61 | AH9: =IF('02_Common_Member_Master'!H9="","",'02_Common_Member_Master'!H9) -> 70 | AI9: =IF('02_Common_Member_Master'!C9="","",'02_Common_Member_Master'!C9) -> 7
A10: =IF('02_Common_Member_Master'!A10="","",'02_Common_Member_Master'!A10) -> 8 | D10: =IF('02_Common_Member_Master'!I10="","",'02_Common_Member_Master'!I10) -> Gulam Husain Kutbullah Khan | E10: =IF('02_Common_Member_Master'!J10="","",'02_Common_Member_Master'!J10) | F10: =IF('02_Common_Member_Master'!K10="","",'02_Common_Member_Master'!K10) | G10: =IF('02_Common_Member_Master'!L10="","",'02_Common_Member_Master'!L10) | H10: =IF('02_Common_Member_Master'!M10="","",'02_Common_Member_Master'!M10) | I10: =IF('02_Common_Member_Master'!N10="","",'02_Common_Member_Master'!N10) | J10: =IF('02_Common_Member_Master'!#REF!="","",'02_Common_Member_Master'!#REF!) -> #REF! | K10: =IF('02_Common_Member_Master'!#REF!="","",'02_Common_Member_Master'!#REF!) -> #REF! | L10: =IF('02_Common_Member_Master'!#REF!="","",'02_Common_Member_Master'!#REF!) -> #REF! | AF10: =IF('02_Common_Member_Master'!D10="","",'02_Common_Member_Master'!D10) -> 10 (Ten) | AG10: =IF('02_Common_Member_Master'!G10="","",'02_Common_Member_Master'!G10) -> 71 | AH10: =IF('02_Common_Member_Master'!H10="","",'02_Common_Member_Master'!H10) -> 80 | AI10: =IF('02_Common_Member_Master'!C10="","",'02_Common_Member_Master'!C10) -> 8
A11: =IF('02_Common_Member_Master'!A11="","",'02_Common_Member_Master'!A11) -> 9 | D11: =IF('02_Common_Member_Master'!I11="","",'02_Common_Member_Master'!I11) -> Sajid Azhar Husain Khan | E11: =IF('02_Common_Member_Master'!J11="","",'02_Common_Member_Master'!J11) | F11: =IF('02_Common_Member_Master'!K11="","",'02_Common_Member_Master'!K11) | G11: =IF('02_Common_Member_Master'!L11="","",'02_Common_Member_Master'!L11) | H11: =IF('02_Common_Member_Master'!M11="","",'02_Common_Member_Master'!M11) | I11: =IF('02_Common_Member_Master'!N11="","",'02_Common_Member_Master'!N11) | J11: =IF('02_Common_Member_Master'!#REF!="","",'02_Common_Member_Master'!#REF!) -> #REF! | K11: =IF('02_Common_Member_Master'!#REF!="","",'02_Common_Member_Master'!#REF!) -> #REF! | L11: =IF('02_Common_Member_Master'!#REF!="","",'02_Common_Member_Master'!#REF!) -> #REF! | AF11: =IF('02_Common_Member_Master'!D11="","",'02_Common_Member_Master'!D11) -> 10 (Ten) | AG11: =IF('02_Common_Member_Master'!G11="","",'02_Common_Member_Master'!G11) -> 81 | AH11: =IF('02_Common_Member_Master'!H11="","",'02_Common_Member_Master'!H11) -> 90 | AI11: =IF('02_Common_Member_Master'!C11="","",'02_Common_Member_Master'!C11) -> 9
A12: =IF('02_Common_Member_Master'!A12="","",'02_Common_Member_Master'!A12) -> 10 | D12: =IF('02_Common_Member_Master'!I12="","",'02_Common_Member_Master'!I12) -> Shakilabanoo Mohamed Iqbal Khan | E12: =IF('02_Common_Member_Master'!J12="","",'02_Common_Member_Master'!J12) | F12: =IF('02_Common_Member_Master'!K12="","",'02_Common_Member_Master'!K12) | G12: =IF('02_Common_Member_Master'!L12="","",'02_Common_Member_Master'!L12) | H12: =IF('02_Common_Member_Master'!M12="","",'02_Common_Member_Master'!M12) | I12: =IF('02_Common_Member_Master'!N12="","",'02_Common_Member_Master'!N12) | J12: =IF('02_Common_Member_Master'!#REF!="","",'02_Common_Member_Master'!#REF!) -> #REF! | K12: =IF('02_Common_Member_Master'!#REF!="","",'02_Common_Member_Master'!#REF!) -> #REF! | L12: =IF('02_Common_Member_Master'!#REF!="","",'02_Common_Member_Master'!#REF!) -> #REF! | AF12: =IF('02_Common_Member_Master'!D12="","",'02_Common_Member_Master'!D12) -> 10 (Ten) | AG12: =IF('02_Common_Member_Master'!G12="","",'02_Common_Member_Master'!G12) -> 91 | AH12: =IF('02_Common_Member_Master'!H12="","",'02_Common_Member_Master'!H12) -> 100 | AI12: =IF('02_Common_Member_Master'!C12="","",'02_Common_Member_Master'!C12) -> 10
A13: =IF('02_Common_Member_Master'!A13="","",'02_Common_Member_Master'!A13) -> 11 | D13: =IF('02_Common_Member_Master'!I13="","",'02_Common_Member_Master'!I13) -> Mohd Hashim Anwarul Haque Khan | E13: =IF('02_Common_Member_Master'!J13="","",'02_Common_Member_Master'!J13) | F13: =IF('02_Common_Member_Master'!K13="","",'02_Common_Member_Master'!K13) | G13: =IF('02_Common_Member_Master'!L13="","",'02_Common_Member_Master'!L13) | H13: =IF('02_Common_Member_Master'!M13="","",'02_Common_Member_Master'!M13) | I13: =IF('02_Common_Member_Master'!N13="","",'02_Common_Member_Master'!N13) | J13: =IF('02_Common_Member_Master'!#REF!="","",'02_Common_Member_Master'!#REF!) -> #REF! | K13: =IF('02_Common_Member_Master'!#REF!="","",'02_Common_Member_Master'!#REF!) -> #REF! | L13: =IF('02_Common_Member_Master'!#REF!="","",'02_Common_Member_Master'!#REF!) -> #REF! | AF13: =IF('02_Common_Member_Master'!D13="","",'02_Common_Member_Master'!D13) -> 10 (Ten) | AG13: =IF('02_Common_Member_Master'!G13="","",'02_Common_Member_Master'!G13) -> 101 | AH13: =IF('02_Common_Member_Master'!H13="","",'02_Common_Member_Master'!H13) -> 110 | AI13: =IF('02_Common_Member_Master'!C13="","",'02_Common_Member_Master'!C13) -> 11
A14: =IF('02_Common_Member_Master'!A14="","",'02_Common_Member_Master'!A14) -> 12 | D14: =IF('02_Common_Member_Master'!I14="","",'02_Common_Member_Master'!I14) -> Mohammed Shoyab Mohammed Faique Farooque | E14: =IF('02_Common_Member_Master'!J14="","",'02_Common_Member_Master'!J14) | F14: =IF('02_Common_Member_Master'!K14="","",'02_Common_Member_Master'!K14) | G14: =IF('02_Common_Member_Master'!L14="","",'02_Common_Member_Master'!L14) | H14: =IF('02_Common_Member_Master'!M14="","",'02_Common_Member_Master'!M14) | I14: =IF('02_Common_Member_Master'!N14="","",'02_Common_Member_Master'!N14) | J14: =IF('02_Common_Member_Master'!#REF!="","",'02_Common_Member_Master'!#REF!) -> #REF! | K14: =IF('02_Common_Member_Master'!#REF!="","",'02_Common_Member_Master'!#REF!) -> #REF! | L14: =IF('02_Common_Member_Master'!#REF!="","",'02_Common_Member_Master'!#REF!) -> #REF! | AF14: =IF('02_Common_Member_Master'!D14="","",'02_Common_Member_Master'!D14) -> 10 (Ten) | AG14: =IF('02_Common_Member_Master'!G14="","",'02_Common_Member_Master'!G14) -> 111 | AH14: =IF('02_Common_Member_Master'!H14="","",'02_Common_Member_Master'!H14) -> 120 | AI14: =IF('02_Common_Member_Master'!C14="","",'02_Common_Member_Master'!C14) -> 12
A15: =IF('02_Common_Member_Master'!A15="","",'02_Common_Member_Master'!A15) -> 13 | D15: =IF('02_Common_Member_Master'!I15="","",'02_Common_Member_Master'!I15) -> Ruksana Rashid Ahmed Khan | E15: =IF('02_Common_Member_Master'!J15="","",'02_Common_Member_Master'!J15) | F15: =IF('02_Common_Member_Master'!K15="","",'02_Common_Member_Master'!K15) | G15: =IF('02_Common_Member_Master'!L15="","",'02_Common_Member_Master'!L15) | H15: =IF('02_Common_Member_Master'!M15="","",'02_Common_Member_Master'!M15) | I15: =IF('02_Common_Member_Master'!N15="","",'02_Common_Member_Master'!N15) | J15: =IF('02_Common_Member_Master'!#REF!="","",'02_Common_Member_Master'!#REF!) -> #REF! | K15: =IF('02_Common_Member_Master'!#REF!="","",'02_Common_Member_Master'!#REF!) -> #REF! | L15: =IF('02_Common_Member_Master'!#REF!="","",'02_Common_Member_Master'!#REF!) -> #REF! | AF15: =IF('02_Common_Member_Master'!D15="","",'02_Common_Member_Master'!D15) -> 10 (Ten) | AG15: =IF('02_Common_Member_Master'!G15="","",'02_Common_Member_Master'!G15) -> 121 | AH15: =IF('02_Common_Member_Master'!H15="","",'02_Common_Member_Master'!H15) -> 130 | AI15: =IF('02_Common_Member_Master'!C15="","",'02_Common_Member_Master'!C15) -> 13
A16: =IF('02_Common_Member_Master'!A16="","",'02_Common_Member_Master'!A16) -> 14 | D16: =IF('02_Common_Member_Master'!I16="","",'02_Common_Member_Master'!I16) -> Mohd Akhtar Ramzan Khan | E16: =IF('02_Common_Member_Master'!J16="","",'02_Common_Member_Master'!J16) | F16: =IF('02_Common_Member_Master'!K16="","",'02_Common_Member_Master'!K16) | G16: =IF('02_Common_Member_Master'!L16="","",'02_Common_Member_Master'!L16) | H16: =IF('02_Common_Member_Master'!M16="","",'02_Common_Member_Master'!M16) | I16: =IF('02_Common_Member_Master'!N16="","",'02_Common_Member_Master'!N16) | J16: =IF('02_Common_Member_Master'!#REF!="","",'02_Common_Member_Master'!#REF!) -> #REF! | K16: =IF('02_Common_Member_Master'!#REF!="","",'02_Common_Member_Master'!#REF!) -> #REF! | L16: =IF('02_Common_Member_Master'!#REF!="","",'02_Common_Member_Master'!#REF!) -> #REF! | AF16: =IF('02_Common_Member_Master'!D16="","",'02_Common_Member_Master'!D16) -> 10 (Ten) | AG16: =IF('02_Common_Member_Master'!G16="","",'02_Common_Member_Master'!G16) -> 131 | AH16: =IF('02_Common_Member_Master'!H16="","",'02_Common_Member_Master'!H16) -> 140 | AI16: =IF('02_Common_Member_Master'!C16="","",'02_Common_Member_Master'!C16) -> 14
... A23: =IF('02_Common_Member_Master'!A23="","",'02_Common_Member_Master'!A23) -> 21 | D23: =IF('02_Common_Member_Master'!I23="","",'02_Common_Member_Master'!I23) -> Sarfaraz Israr Khan | E23: =IF('02_Common_Member_Master'!J23="","",'02_Common_Member_Master'!J23) | F23: =IF('02_Common_Member_Master'!K23="","",'02_Common_Member_Master'!K23) | G23: =IF('02_Common_Member_Master'!L23="","",'02_Common_Member_Master'!L23) | H23: =IF('02_Common_Member_Master'!M23="","",'02_Common_Member_Master'!M23) | I23: =IF('02_Common_Member_Master'!N23="","",'02_Common_Member_Master'!N23) | J23: =IF('02_Common_Member_Master'!#REF!="","",'02_Common_Member_Master'!#REF!) -> #REF! | K23: =IF('02_Common_Member_Master'!#REF!="","",'02_Common_Member_Master'!#REF!) -> #REF! | L23: =IF('02_Common_Member_Master'!#REF!="","",'02_Common_Member_Master'!#REF!) -> #REF! | AF23: =IF('02_Common_Member_Master'!D23="","",'02_Common_Member_Master'!D23) -> 10 (Ten) | AG23: =IF('02_Common_Member_Master'!G23="","",'02_Common_Member_Master'!G23) -> 201 | AH23: =IF('02_Common_Member_Master'!H23="","",'02_Common_Member_Master'!H23) -> 210 | AI23: =IF('02_Common_Member_Master'!C23="","",'02_Common_Member_Master'!C23) -> 21

Sheet 04_Form_J
A1: Sr. No. | B1: Members Name Full | H1: Permanent Address | J1: Class of Member
B2: 1 | C2: 2 | D2: 3 | E2: 4 | F2: 5 | G2: 6 | H2: Flat/Room/Shop/Office/Gala No. | I2: Wing No.
A3: =IF('02_Common_Member_Master'!A3="","",'02_Common_Member_Master'!A3) -> 1 | B3: =IF('02_Common_Member_Master'!I3="","",'02_Common_Member_Master'!I3) -> Nafisha Khatoon Sharif Ahmed Khan | C3: =IF('02_Common_Member_Master'!J3="","",'02_Common_Member_Master'!J3) | D3: =IF('02_Common_Member_Master'!K3="","",'02_Common_Member_Master'!K3) | E3: =IF('02_Common_Member_Master'!L3="","",'02_Common_Member_Master'!L3) | F3: =IF('02_Common_Member_Master'!M3="","",'02_Common_Member_Master'!M3) | G3: =IF('02_Common_Member_Master'!N3="","",'02_Common_Member_Master'!N3) | H3: =IF('02_Common_Member_Master'!#REF!="","",'02_Common_Member_Master'!#REF!) -> #REF! | I3: =IF('02_Common_Member_Master'!#REF!="","",'02_Common_Member_Master'!#REF!) -> #REF!
A4: =IF('02_Common_Member_Master'!A4="","",'02_Common_Member_Master'!A4) -> 2 | B4: =IF('02_Common_Member_Master'!I4="","",'02_Common_Member_Master'!I4) -> Azhar Husain Mazhar Husain Khan | C4: =IF('02_Common_Member_Master'!J4="","",'02_Common_Member_Master'!J4) | D4: =IF('02_Common_Member_Master'!K4="","",'02_Common_Member_Master'!K4) | E4: =IF('02_Common_Member_Master'!L4="","",'02_Common_Member_Master'!L4) | F4: =IF('02_Common_Member_Master'!M4="","",'02_Common_Member_Master'!M4) | G4: =IF('02_Common_Member_Master'!N4="","",'02_Common_Member_Master'!N4) | H4: =IF('02_Common_Member_Master'!#REF!="","",'02_Common_Member_Master'!#REF!) -> #REF! | I4: =IF('02_Common_Member_Master'!#REF!="","",'02_Common_Member_Master'!#REF!) -> #REF!
A5: =IF('02_Common_Member_Master'!A5="","",'02_Common_Member_Master'!A5) -> 3 | B5: =IF('02_Common_Member_Master'!I5="","",'02_Common_Member_Master'!I5) -> Abdul Malik Azhar Husain Khan | C5: =IF('02_Common_Member_Master'!J5="","",'02_Common_Member_Master'!J5) | D5: =IF('02_Common_Member_Master'!K5="","",'02_Common_Member_Master'!K5) | E5: =IF('02_Common_Member_Master'!L5="","",'02_Common_Member_Master'!L5) | F5: =IF('02_Common_Member_Master'!M5="","",'02_Common_Member_Master'!M5) | G5: =IF('02_Common_Member_Master'!N5="","",'02_Common_Member_Master'!N5) | H5: =IF('02_Common_Member_Master'!#REF!="","",'02_Common_Member_Master'!#REF!) -> #REF! | I5: =IF('02_Common_Member_Master'!#REF!="","",'02_Common_Member_Master'!#REF!) -> #REF!
A6: =IF('02_Common_Member_Master'!A6="","",'02_Common_Member_Master'!A6) -> 4 | B6: =IF('02_Common_Member_Master'!I6="","",'02_Common_Member_Master'!I6) -> Abdul Wadood Abdul Mannan Sayyed | C6: =IF('02_Common_Member_Master'!J6="","",'02_Common_Member_Master'!J6) | D6: =IF('02_Common_Member_Master'!K6="","",'02_Common_Member_Master'!K6) | E6: =IF('02_Common_Member_Master'!L6="","",'02_Common_Member_Master'!L6) | F6: =IF('02_Common_Member_Master'!M6="","",'02_Common_Member_Master'!M6) | G6: =IF('02_Common_Member_Master'!N6="","",'02_Common_Member_Master'!N6) | H6: =IF('02_Common_Member_Master'!#REF!="","",'02_Common_Member_Master'!#REF!) -> #REF! | I6: =IF('02_Common_Member_Master'!#REF!="","",'02_Common_Member_Master'!#REF!) -> #REF!
A7: =IF('02_Common_Member_Master'!A7="","",'02_Common_Member_Master'!A7) -> 5 | B7: =IF('02_Common_Member_Master'!I7="","",'02_Common_Member_Master'!I7) -> Abdulhai Abdul Mannan Sayyed | C7: =IF('02_Common_Member_Master'!J7="","",'02_Common_Member_Master'!J7) | D7: =IF('02_Common_Member_Master'!K7="","",'02_Common_Member_Master'!K7) | E7: =IF('02_Common_Member_Master'!L7="","",'02_Common_Member_Master'!L7) | F7: =IF('02_Common_Member_Master'!M7="","",'02_Common_Member_Master'!M7) | G7: =IF('02_Common_Member_Master'!N7="","",'02_Common_Member_Master'!N7) | H7: =IF('02_Common_Member_Master'!#REF!="","",'02_Common_Member_Master'!#REF!) -> #REF! | I7: =IF('02_Common_Member_Master'!#REF!="","",'02_Common_Member_Master'!#REF!) -> #REF!
A8: =IF('02_Common_Member_Master'!A8="","",'02_Common_Member_Master'!A8) -> 6 | B8: =IF('02_Common_Member_Master'!I8="","",'02_Common_Member_Master'!I8) -> Shakeel Ahmed Nazir Ahmed Khan | C8: =IF('02_Common_Member_Master'!J8="","",'02_Common_Member_Master'!J8) | D8: =IF('02_Common_Member_Master'!K8="","",'02_Common_Member_Master'!K8) | E8: =IF('02_Common_Member_Master'!L8="","",'02_Common_Member_Master'!L8) | F8: =IF('02_Common_Member_Master'!M8="","",'02_Common_Member_Master'!M8) | G8: =IF('02_Common_Member_Master'!N8="","",'02_Common_Member_Master'!N8) | H8: =IF('02_Common_Member_Master'!#REF!="","",'02_Common_Member_Master'!#REF!) -> #REF! | I8: =IF('02_Common_Member_Master'!#REF!="","",'02_Common_Member_Master'!#REF!) -> #REF!
A9: =IF('02_Common_Member_Master'!A9="","",'02_Common_Member_Master'!A9) -> 7 | B9: =IF('02_Common_Member_Master'!I9="","",'02_Common_Member_Master'!I9) -> Mohammed Nawaz Ramzan Ali Shaikh | C9: =IF('02_Common_Member_Master'!J9="","",'02_Common_Member_Master'!J9) | D9: =IF('02_Common_Member_Master'!K9="","",'02_Common_Member_Master'!K9) | E9: =IF('02_Common_Member_Master'!L9="","",'02_Common_Member_Master'!L9) | F9: =IF('02_Common_Member_Master'!M9="","",'02_Common_Member_Master'!M9) | G9: =IF('02_Common_Member_Master'!N9="","",'02_Common_Member_Master'!N9) | H9: =IF('02_Common_Member_Master'!#REF!="","",'02_Common_Member_Master'!#REF!) -> #REF! | I9: =IF('02_Common_Member_Master'!#REF!="","",'02_Common_Member_Master'!#REF!) -> #REF!
A10: =IF('02_Common_Member_Master'!A10="","",'02_Common_Member_Master'!A10) -> 8 | B10: =IF('02_Common_Member_Master'!I10="","",'02_Common_Member_Master'!I10) -> Gulam Husain Kutbullah Khan | C10: =IF('02_Common_Member_Master'!J10="","",'02_Common_Member_Master'!J10) | D10: =IF('02_Common_Member_Master'!K10="","",'02_Common_Member_Master'!K10) | E10: =IF('02_Common_Member_Master'!L10="","",'02_Common_Member_Master'!L10) | F10: =IF('02_Common_Member_Master'!M10="","",'02_Common_Member_Master'!M10) | G10: =IF('02_Common_Member_Master'!N10="","",'02_Common_Member_Master'!N10) | H10: =IF('02_Common_Member_Master'!#REF!="","",'02_Common_Member_Master'!#REF!) -> #REF! | I10: =IF('02_Common_Member_Master'!#REF!="","",'02_Common_Member_Master'!#REF!) -> #REF!
A11: =IF('02_Common_Member_Master'!A11="","",'02_Common_Member_Master'!A11) -> 9 | B11: =IF('02_Common_Member_Master'!I11="","",'02_Common_Member_Master'!I11) -> Sajid Azhar Husain Khan | C11: =IF('02_Common_Member_Master'!J11="","",'02_Common_Member_Master'!J11) | D11: =IF('02_Common_Member_Master'!K11="","",'02_Common_Member_Master'!K11) | E11: =IF('02_Common_Member_Master'!L11="","",'02_Common_Member_Master'!L11) | F11: =IF('02_Common_Member_Master'!M11="","",'02_Common_Member_Master'!M11) | G11: =IF('02_Common_Member_Master'!N11="","",'02_Common_Member_Master'!N11) | H11: =IF('02_Common_Member_Master'!#REF!="","",'02_Common_Member_Master'!#REF!) -> #REF! | I11: =IF('02_Common_Member_Master'!#REF!="","",'02_Common_Member_Master'!#REF!) -> #REF!
A12: =IF('02_Common_Member_Master'!A12="","",'02_Common_Member_Master'!A12) -> 10 | B12: =IF('02_Common_Member_Master'!I12="","",'02_Common_Member_Master'!I12) -> Shakilabanoo Mohamed Iqbal Khan | C12: =IF('02_Common_Member_Master'!J12="","",'02_Common_Member_Master'!J12) | D12: =IF('02_Common_Member_Master'!K12="","",'02_Common_Member_Master'!K12) | E12: =IF('02_Common_Member_Master'!L12="","",'02_Common_Member_Master'!L12) | F12: =IF('02_Common_Member_Master'!M12="","",'02_Common_Member_Master'!M12) | G12: =IF('02_Common_Member_Master'!N12="","",'02_Common_Member_Master'!N12) | H12: =IF('02_Common_Member_Master'!#REF!="","",'02_Common_Member_Master'!#REF!) -> #REF! | I12: =IF('02_Common_Member_Master'!#REF!="","",'02_Common_Member_Master'!#REF!) -> #REF!
A13: =IF('02_Common_Member_Master'!A13="","",'02_Common_Member_Master'!A13) -> 11 | B13: =IF('02_Common_Member_Master'!I13="","",'02_Common_Member_Master'!I13) -> Mohd Hashim Anwarul Haque Khan | C13: =IF('02_Common_Member_Master'!J13="","",'02_Common_Member_Master'!J13) | D13: =IF('02_Common_Member_Master'!K13="","",'02_Common_Member_Master'!K13) | E13: =IF('02_Common_Member_Master'!L13="","",'02_Common_Member_Master'!L13) | F13: =IF('02_Common_Member_Master'!M13="","",'02_Common_Member_Master'!M13) | G13: =IF('02_Common_Member_Master'!N13="","",'02_Common_Member_Master'!N13) | H13: =IF('02_Common_Member_Master'!#REF!="","",'02_Common_Member_Master'!#REF!) -> #REF! | I13: =IF('02_Common_Member_Master'!#REF!="","",'02_Common_Member_Master'!#REF!) -> #REF!
A14: =IF('02_Common_Member_Master'!A14="","",'02_Common_Member_Master'!A14) -> 12 | B14: =IF('02_Common_Member_Master'!I14="","",'02_Common_Member_Master'!I14) -> Mohammed Shoyab Mohammed Faique Farooque | C14: =IF('02_Common_Member_Master'!J14="","",'02_Common_Member_Master'!J14) | D14: =IF('02_Common_Member_Master'!K14="","",'02_Common_Member_Master'!K14) | E14: =IF('02_Common_Member_Master'!L14="","",'02_Common_Member_Master'!L14) | F14: =IF('02_Common_Member_Master'!M14="","",'02_Common_Member_Master'!M14) | G14: =IF('02_Common_Member_Master'!N14="","",'02_Common_Member_Master'!N14) | H14: =IF('02_Common_Member_Master'!#REF!="","",'02_Common_Member_Master'!#REF!) -> #REF! | I14: =IF('02_Common_Member_Master'!#REF!="","",'02_Common_Member_Master'!#REF!) -> #REF!
... A23: =IF('02_Common_Member_Master'!A23="","",'02_Common_Member_Master'!A23) -> 21 | B23: =IF('02_Common_Member_Master'!I23="","",'02_Common_Member_Master'!I23) -> Sarfaraz Israr Khan | C23: =IF('02_Common_Member_Master'!J23="","",'02_Common_Member_Master'!J23) | D23: =IF('02_Common_Member_Master'!K23="","",'02_Common_Member_Master'!K23) | E23: =IF('02_Common_Member_Master'!L23="","",'02_Common_Member_Master'!L23) | F23: =IF('02_Common_Member_Master'!M23="","",'02_Common_Member_Master'!M23) | G23: =IF('02_Common_Member_Master'!N23="","",'02_Common_Member_Master'!N23) | H23: =IF('02_Common_Member_Master'!#REF!="","",'02_Common_Member_Master'!#REF!) -> #REF! | I23: =IF('02_Common_Member_Master'!#REF!="","",'02_Common_Member_Master'!#REF!) -> #REF!

Sheet 05_Share_Register
A1: Sr. No. | B1: Date of allotment of Share | C1: Cash Book folio No. | D1: Share Certificate No. | E1: No. of Shares | F1: Value of One Share | G1: Value of Shares | H1: Address | J1: Members Name Full | P1: Details of Shares Transferred or Refunded
H2: Flat/Room/Shop/Office/Gala No. | I2: Wing No. | J2: 1 | K2: 2 | L2: 3 | M2: 4 | N2: 5 | O2: 6 | P2: Date of transfer / refund | Q2: Cash Book Journal Folio No. | R2: No. of Shares Transferred/Refunded From | S2: No. of Shares Transferred/Refunded To | T2: Share Certificate No. transferred or refunded | U2: Share Value transferred or refunded Rs. | V2: Name of the transferee or person receiving refund | W2: Authority for transfer or refund | X2: Remark
A3: =IF('02_Common_Member_Master'!A3="","",'02_Common_Member_Master'!A3) -> 1 | D3: =IF('02_Common_Member_Master'!C3="","",'02_Common_Member_Master'!C3) -> 1 | E3: =IF('02_Common_Member_Master'!D3="","",'02_Common_Member_Master'!D3) -> 10 (Ten) | F3: =IF('02_Common_Member_Master'!E3="","",'02_Common_Member_Master'!E3) -> 50/- Each | G3: =IF('02_Common_Member_Master'!F3="","",'02_Common_Member_Master'!F3) -> 500/- | H3: =IF('02_Common_Member_Master'!#REF!="","",'02_Common_Member_Master'!#REF!) -> #REF! | I3: =IF('02_Common_Member_Master'!#REF!="","",'02_Common_Member_Master'!#REF!) -> #REF! | J3: =IF('02_Common_Member_Master'!I3="","",'02_Common_Member_Master'!I3) -> Nafisha Khatoon Sharif Ahmed Khan | K3: =IF('02_Common_Member_Master'!J3="","",'02_Common_Member_Master'!J3) | L3: =IF('02_Common_Member_Master'!K3="","",'02_Common_Member_Master'!K3) | M3: =IF('02_Common_Member_Master'!L3="","",'02_Common_Member_Master'!L3) | N3: =IF('02_Common_Member_Master'!M3="","",'02_Common_Member_Master'!M3) | O3: =IF('02_Common_Member_Master'!N3="","",'02_Common_Member_Master'!N3)
A4: =IF('02_Common_Member_Master'!A4="","",'02_Common_Member_Master'!A4) -> 2 | D4: =IF('02_Common_Member_Master'!C4="","",'02_Common_Member_Master'!C4) -> 2 | E4: =IF('02_Common_Member_Master'!D4="","",'02_Common_Member_Master'!D4) -> 10 (Ten) | F4: =IF('02_Common_Member_Master'!E4="","",'02_Common_Member_Master'!E4) -> 50/- Each | G4: =IF('02_Common_Member_Master'!F4="","",'02_Common_Member_Master'!F4) -> 500/- | H4: =IF('02_Common_Member_Master'!#REF!="","",'02_Common_Member_Master'!#REF!) -> #REF! | I4: =IF('02_Common_Member_Master'!#REF!="","",'02_Common_Member_Master'!#REF!) -> #REF! | J4: =IF('02_Common_Member_Master'!I4="","",'02_Common_Member_Master'!I4) -> Azhar Husain Mazhar Husain Khan | K4: =IF('02_Common_Member_Master'!J4="","",'02_Common_Member_Master'!J4) | L4: =IF('02_Common_Member_Master'!K4="","",'02_Common_Member_Master'!K4) | M4: =IF('02_Common_Member_Master'!L4="","",'02_Common_Member_Master'!L4) | N4: =IF('02_Common_Member_Master'!M4="","",'02_Common_Member_Master'!M4) | O4: =IF('02_Common_Member_Master'!N4="","",'02_Common_Member_Master'!N4)
A5: =IF('02_Common_Member_Master'!A5="","",'02_Common_Member_Master'!A5) -> 3 | D5: =IF('02_Common_Member_Master'!C5="","",'02_Common_Member_Master'!C5) -> 3 | E5: =IF('02_Common_Member_Master'!D5="","",'02_Common_Member_Master'!D5) -> 10 (Ten) | F5: =IF('02_Common_Member_Master'!E5="","",'02_Common_Member_Master'!E5) -> 50/- Each | G5: =IF('02_Common_Member_Master'!F5="","",'02_Common_Member_Master'!F5) -> 500/- | H5: =IF('02_Common_Member_Master'!#REF!="","",'02_Common_Member_Master'!#REF!) -> #REF! | I5: =IF('02_Common_Member_Master'!#REF!="","",'02_Common_Member_Master'!#REF!) -> #REF! | J5: =IF('02_Common_Member_Master'!I5="","",'02_Common_Member_Master'!I5) -> Abdul Malik Azhar Husain Khan | K5: =IF('02_Common_Member_Master'!J5="","",'02_Common_Member_Master'!J5) | L5: =IF('02_Common_Member_Master'!K5="","",'02_Common_Member_Master'!K5) | M5: =IF('02_Common_Member_Master'!L5="","",'02_Common_Member_Master'!L5) | N5: =IF('02_Common_Member_Master'!M5="","",'02_Common_Member_Master'!M5) | O5: =IF('02_Common_Member_Master'!N5="","",'02_Common_Member_Master'!N5)
A6: =IF('02_Common_Member_Master'!A6="","",'02_Common_Member_Master'!A6) -> 4 | D6: =IF('02_Common_Member_Master'!C6="","",'02_Common_Member_Master'!C6) -> 4 | E6: =IF('02_Common_Member_Master'!D6="","",'02_Common_Member_Master'!D6) -> 10 (Ten) | F6: =IF('02_Common_Member_Master'!E6="","",'02_Common_Member_Master'!E6) -> 50/- Each | G6: =IF('02_Common_Member_Master'!F6="","",'02_Common_Member_Master'!F6) -> 500/- | H6: =IF('02_Common_Member_Master'!#REF!="","",'02_Common_Member_Master'!#REF!) -> #REF! | I6: =IF('02_Common_Member_Master'!#REF!="","",'02_Common_Member_Master'!#REF!) -> #REF! | J6: =IF('02_Common_Member_Master'!I6="","",'02_Common_Member_Master'!I6) -> Abdul Wadood Abdul Mannan Sayyed | K6: =IF('02_Common_Member_Master'!J6="","",'02_Common_Member_Master'!J6) | L6: =IF('02_Common_Member_Master'!K6="","",'02_Common_Member_Master'!K6) | M6: =IF('02_Common_Member_Master'!L6="","",'02_Common_Member_Master'!L6) | N6: =IF('02_Common_Member_Master'!M6="","",'02_Common_Member_Master'!M6) | O6: =IF('02_Common_Member_Master'!N6="","",'02_Common_Member_Master'!N6)
A7: =IF('02_Common_Member_Master'!A7="","",'02_Common_Member_Master'!A7) -> 5 | D7: =IF('02_Common_Member_Master'!C7="","",'02_Common_Member_Master'!C7) -> 5 | E7: =IF('02_Common_Member_Master'!D7="","",'02_Common_Member_Master'!D7) -> 10 (Ten) | F7: =IF('02_Common_Member_Master'!E7="","",'02_Common_Member_Master'!E7) -> 50/- Each | G7: =IF('02_Common_Member_Master'!F7="","",'02_Common_Member_Master'!F7) -> 500/- | H7: =IF('02_Common_Member_Master'!#REF!="","",'02_Common_Member_Master'!#REF!) -> #REF! | I7: =IF('02_Common_Member_Master'!#REF!="","",'02_Common_Member_Master'!#REF!) -> #REF! | J7: =IF('02_Common_Member_Master'!I7="","",'02_Common_Member_Master'!I7) -> Abdulhai Abdul Mannan Sayyed | K7: =IF('02_Common_Member_Master'!J7="","",'02_Common_Member_Master'!J7) | L7: =IF('02_Common_Member_Master'!K7="","",'02_Common_Member_Master'!K7) | M7: =IF('02_Common_Member_Master'!L7="","",'02_Common_Member_Master'!L7) | N7: =IF('02_Common_Member_Master'!M7="","",'02_Common_Member_Master'!M7) | O7: =IF('02_Common_Member_Master'!N7="","",'02_Common_Member_Master'!N7)
A8: =IF('02_Common_Member_Master'!A8="","",'02_Common_Member_Master'!A8) -> 6 | D8: =IF('02_Common_Member_Master'!C8="","",'02_Common_Member_Master'!C8) -> 6 | E8: =IF('02_Common_Member_Master'!D8="","",'02_Common_Member_Master'!D8) -> 10 (Ten) | F8: =IF('02_Common_Member_Master'!E8="","",'02_Common_Member_Master'!E8) -> 50/- Each | G8: =IF('02_Common_Member_Master'!F8="","",'02_Common_Member_Master'!F8) -> 500/- | H8: =IF('02_Common_Member_Master'!#REF!="","",'02_Common_Member_Master'!#REF!) -> #REF! | I8: =IF('02_Common_Member_Master'!#REF!="","",'02_Common_Member_Master'!#REF!) -> #REF! | J8: =IF('02_Common_Member_Master'!I8="","",'02_Common_Member_Master'!I8) -> Shakeel Ahmed Nazir Ahmed Khan | K8: =IF('02_Common_Member_Master'!J8="","",'02_Common_Member_Master'!J8) | L8: =IF('02_Common_Member_Master'!K8="","",'02_Common_Member_Master'!K8) | M8: =IF('02_Common_Member_Master'!L8="","",'02_Common_Member_Master'!L8) | N8: =IF('02_Common_Member_Master'!M8="","",'02_Common_Member_Master'!M8) | O8: =IF('02_Common_Member_Master'!N8="","",'02_Common_Member_Master'!N8)
A9: =IF('02_Common_Member_Master'!A9="","",'02_Common_Member_Master'!A9) -> 7 | D9: =IF('02_Common_Member_Master'!C9="","",'02_Common_Member_Master'!C9) -> 7 | E9: =IF('02_Common_Member_Master'!D9="","",'02_Common_Member_Master'!D9) -> 10 (Ten) | F9: =IF('02_Common_Member_Master'!E9="","",'02_Common_Member_Master'!E9) -> 50/- Each | G9: =IF('02_Common_Member_Master'!F9="","",'02_Common_Member_Master'!F9) -> 500/- | H9: =IF('02_Common_Member_Master'!#REF!="","",'02_Common_Member_Master'!#REF!) -> #REF! | I9: =IF('02_Common_Member_Master'!#REF!="","",'02_Common_Member_Master'!#REF!) -> #REF! | J9: =IF('02_Common_Member_Master'!I9="","",'02_Common_Member_Master'!I9) -> Mohammed Nawaz Ramzan Ali Shaikh | K9: =IF('02_Common_Member_Master'!J9="","",'02_Common_Member_Master'!J9) | L9: =IF('02_Common_Member_Master'!K9="","",'02_Common_Member_Master'!K9) | M9: =IF('02_Common_Member_Master'!L9="","",'02_Common_Member_Master'!L9) | N9: =IF('02_Common_Member_Master'!M9="","",'02_Common_Member_Master'!M9) | O9: =IF('02_Common_Member_Master'!N9="","",'02_Common_Member_Master'!N9)
A10: =IF('02_Common_Member_Master'!A10="","",'02_Common_Member_Master'!A10) -> 8 | D10: =IF('02_Common_Member_Master'!C10="","",'02_Common_Member_Master'!C10) -> 8 | E10: =IF('02_Common_Member_Master'!D10="","",'02_Common_Member_Master'!D10) -> 10 (Ten) | F10: =IF('02_Common_Member_Master'!E10="","",'02_Common_Member_Master'!E10) -> 50/- Each | G10: =IF('02_Common_Member_Master'!F10="","",'02_Common_Member_Master'!F10) -> 500/- | H10: =IF('02_Common_Member_Master'!#REF!="","",'02_Common_Member_Master'!#REF!) -> #REF! | I10: =IF('02_Common_Member_Master'!#REF!="","",'02_Common_Member_Master'!#REF!) -> #REF! | J10: =IF('02_Common_Member_Master'!I10="","",'02_Common_Member_Master'!I10) -> Gulam Husain Kutbullah Khan | K10: =IF('02_Common_Member_Master'!J10="","",'02_Common_Member_Master'!J10) | L10: =IF('02_Common_Member_Master'!K10="","",'02_Common_Member_Master'!K10) | M10: =IF('02_Common_Member_Master'!L10="","",'02_Common_Member_Master'!L10) | N10: =IF('02_Common_Member_Master'!M10="","",'02_Common_Member_Master'!M10) | O10: =IF('02_Common_Member_Master'!N10="","",'02_Common_Member_Master'!N10)
A11: =IF('02_Common_Member_Master'!A11="","",'02_Common_Member_Master'!A11) -> 9 | D11: =IF('02_Common_Member_Master'!C11="","",'02_Common_Member_Master'!C11) -> 9 | E11: =IF('02_Common_Member_Master'!D11="","",'02_Common_Member_Master'!D11) -> 10 (Ten) | F11: =IF('02_Common_Member_Master'!E11="","",'02_Common_Member_Master'!E11) -> 50/- Each | G11: =IF('02_Common_Member_Master'!F11="","",'02_Common_Member_Master'!F11) -> 500/- | H11: =IF('02_Common_Member_Master'!#REF!="","",'02_Common_Member_Master'!#REF!) -> #REF! | I11: =IF('02_Common_Member_Master'!#REF!="","",'02_Common_Member_Master'!#REF!) -> #REF! | J11: =IF('02_Common_Member_Master'!I11="","",'02_Common_Member_Master'!I11) -> Sajid Azhar Husain Khan | K11: =IF('02_Common_Member_Master'!J11="","",'02_Common_Member_Master'!J11) | L11: =IF('02_Common_Member_Master'!K11="","",'02_Common_Member_Master'!K11) | M11: =IF('02_Common_Member_Master'!L11="","",'02_Common_Member_Master'!L11) | N11: =IF('02_Common_Member_Master'!M11="","",'02_Common_Member_Master'!M11) | O11: =IF('02_Common_Member_Master'!N11="","",'02_Common_Member_Master'!N11)
A12: =IF('02_Common_Member_Master'!A12="","",'02_Common_Member_Master'!A12) -> 10 | D12: =IF('02_Common_Member_Master'!C12="","",'02_Common_Member_Master'!C12) -> 10 | E12: =IF('02_Common_Member_Master'!D12="","",'02_Common_Member_Master'!D12) -> 10 (Ten) | F12: =IF('02_Common_Member_Master'!E12="","",'02_Common_Member_Master'!E12) -> 50/- Each | G12: =IF('02_Common_Member_Master'!F12="","",'02_Common_Member_Master'!F12) -> 500/- | H12: =IF('02_Common_Member_Master'!#REF!="","",'02_Common_Member_Master'!#REF!) -> #REF! | I12: =IF('02_Common_Member_Master'!#REF!="","",'02_Common_Member_Master'!#REF!) -> #REF! | J12: =IF('02_Common_Member_Master'!I12="","",'02_Common_Member_Master'!I12) -> Shakilabanoo Mohamed Iqbal Khan | K12: =IF('02_Common_Member_Master'!J12="","",'02_Common_Member_Master'!J12) | L12: =IF('02_Common_Member_Master'!K12="","",'02_Common_Member_Master'!K12) | M12: =IF('02_Common_Member_Master'!L12="","",'02_Common_Member_Master'!L12) | N12: =IF('02_Common_Member_Master'!M12="","",'02_Common_Member_Master'!M12) | O12: =IF('02_Common_Member_Master'!N12="","",'02_Common_Member_Master'!N12)
A13: =IF('02_Common_Member_Master'!A13="","",'02_Common_Member_Master'!A13) -> 11 | D13: =IF('02_Common_Member_Master'!C13="","",'02_Common_Member_Master'!C13) -> 11 | E13: =IF('02_Common_Member_Master'!D13="","",'02_Common_Member_Master'!D13) -> 10 (Ten) | F13: =IF('02_Common_Member_Master'!E13="","",'02_Common_Member_Master'!E13) -> 50/- Each | G13: =IF('02_Common_Member_Master'!F13="","",'02_Common_Member_Master'!F13) -> 500/- | H13: =IF('02_Common_Member_Master'!#REF!="","",'02_Common_Member_Master'!#REF!) -> #REF! | I13: =IF('02_Common_Member_Master'!#REF!="","",'02_Common_Member_Master'!#REF!) -> #REF! | J13: =IF('02_Common_Member_Master'!I13="","",'02_Common_Member_Master'!I13) -> Mohd Hashim Anwarul Haque Khan | K13: =IF('02_Common_Member_Master'!J13="","",'02_Common_Member_Master'!J13) | L13: =IF('02_Common_Member_Master'!K13="","",'02_Common_Member_Master'!K13) | M13: =IF('02_Common_Member_Master'!L13="","",'02_Common_Member_Master'!L13) | N13: =IF('02_Common_Member_Master'!M13="","",'02_Common_Member_Master'!M13) | O13: =IF('02_Common_Member_Master'!N13="","",'02_Common_Member_Master'!N13)
A14: =IF('02_Common_Member_Master'!A14="","",'02_Common_Member_Master'!A14) -> 12 | D14: =IF('02_Common_Member_Master'!C14="","",'02_Common_Member_Master'!C14) -> 12 | E14: =IF('02_Common_Member_Master'!D14="","",'02_Common_Member_Master'!D14) -> 10 (Ten) | F14: =IF('02_Common_Member_Master'!E14="","",'02_Common_Member_Master'!E14) -> 50/- Each | G14: =IF('02_Common_Member_Master'!F14="","",'02_Common_Member_Master'!F14) -> 500/- | H14: =IF('02_Common_Member_Master'!#REF!="","",'02_Common_Member_Master'!#REF!) -> #REF! | I14: =IF('02_Common_Member_Master'!#REF!="","",'02_Common_Member_Master'!#REF!) -> #REF! | J14: =IF('02_Common_Member_Master'!I14="","",'02_Common_Member_Master'!I14) -> Mohammed Shoyab Mohammed Faique Farooque | K14: =IF('02_Common_Member_Master'!J14="","",'02_Common_Member_Master'!J14) | L14: =IF('02_Common_Member_Master'!K14="","",'02_Common_Member_Master'!K14) | M14: =IF('02_Common_Member_Master'!L14="","",'02_Common_Member_Master'!L14) | N14: =IF('02_Common_Member_Master'!M14="","",'02_Common_Member_Master'!M14) | O14: =IF('02_Common_Member_Master'!N14="","",'02_Common_Member_Master'!N14)
... A23: =IF('02_Common_Member_Master'!A23="","",'02_Common_Member_Master'!A23) -> 21 | D23: =IF('02_Common_Member_Master'!C23="","",'02_Common_Member_Master'!C23) -> 21 | E23: =IF('02_Common_Member_Master'!D23="","",'02_Common_Member_Master'!D23) -> 10 (Ten) | F23: =IF('02_Common_Member_Master'!E23="","",'02_Common_Member_Master'!E23) -> 50/- Each | G23: =IF('02_Common_Member_Master'!F23="","",'02_Common_Member_Master'!F23) -> 500/- | H23: =IF('02_Common_Member_Master'!#REF!="","",'02_Common_Member_Master'!#REF!) -> #REF! | I23: =IF('02_Common_Member_Master'!#REF!="","",'02_Common_Member_Master'!#REF!) -> #REF! | J23: =IF('02_Common_Member_Master'!I23="","",'02_Common_Member_Master'!I23) -> Sarfaraz Israr Khan | K23: =IF('02_Common_Member_Master'!J23="","",'02_Common_Member_Master'!J23) | L23: =IF('02_Common_Member_Master'!K23="","",'02_Common_Member_Master'!K23) | M23: =IF('02_Common_Member_Master'!L23="","",'02_Common_Member_Master'!L23) | N23: =IF('02_Common_Member_Master'!M23="","",'02_Common_Member_Master'!M23) | O23: =IF('02_Common_Member_Master'!N23="","",'02_Common_Member_Master'!N23)

Sheet 06_Nomination_Register
A1: Sr. No. | B1: Member Name | H1: Flat / Wing | J1: Date of Nomination | K1: Name/s of Nominee/s & Addresses of the Nominee/s | Q1: Percentage % | W1: Managing Committee Meeting Date | X1: Revocation Date | Y1: Remarks
B2: 1 | C2: 2 | D2: 3 | E2: 4 | F2: 5 | G2: 6 | H2: Flat No. | I2: Wing No. | K2: 1 | L2: 2 | M2: 3 | N2: 4 | O2: 5 | P2: 6 | Q2: 1 | R2: 2 | S2: 3 | T2: 4 | U2: 5 | V2: 6
A3: =IF('02_Common_Member_Master'!A3="","",'02_Common_Member_Master'!A3) -> 1 | B3: =IF('02_Common_Member_Master'!I3="","",'02_Common_Member_Master'!I3) -> Nafisha Khatoon Sharif Ahmed Khan | C3: =IF('02_Common_Member_Master'!J3="","",'02_Common_Member_Master'!J3) | D3: =IF('02_Common_Member_Master'!K3="","",'02_Common_Member_Master'!K3) | E3: =IF('02_Common_Member_Master'!L3="","",'02_Common_Member_Master'!L3) | F3: =IF('02_Common_Member_Master'!M3="","",'02_Common_Member_Master'!M3) | G3: =IF('02_Common_Member_Master'!N3="","",'02_Common_Member_Master'!N3) | H3: =IF('02_Common_Member_Master'!#REF!="","",'02_Common_Member_Master'!#REF!) -> #REF! | I3: =IF('02_Common_Member_Master'!#REF!="","",'02_Common_Member_Master'!#REF!) -> #REF!
A4: =IF('02_Common_Member_Master'!A4="","",'02_Common_Member_Master'!A4) -> 2 | B4: =IF('02_Common_Member_Master'!I4="","",'02_Common_Member_Master'!I4) -> Azhar Husain Mazhar Husain Khan | C4: =IF('02_Common_Member_Master'!J4="","",'02_Common_Member_Master'!J4) | D4: =IF('02_Common_Member_Master'!K4="","",'02_Common_Member_Master'!K4) | E4: =IF('02_Common_Member_Master'!L4="","",'02_Common_Member_Master'!L4) | F4: =IF('02_Common_Member_Master'!M4="","",'02_Common_Member_Master'!M4) | G4: =IF('02_Common_Member_Master'!N4="","",'02_Common_Member_Master'!N4) | H4: =IF('02_Common_Member_Master'!#REF!="","",'02_Common_Member_Master'!#REF!) -> #REF! | I4: =IF('02_Common_Member_Master'!#REF!="","",'02_Common_Member_Master'!#REF!) -> #REF!
