Workbook

Sheet 01_Society_Master
A1: Sr. No. | B1: Field | C1: Value | D1: Line 1 | E1: Line 2 | F1: Line 3 | G1: Line 4 | H1: Line 5 | I1: Line 6
A2: 1 | B2: Society Name
A3: 2 | B3: Society Registration No.
A4: 3 | B4: Society Registration Date
A5: 4 | B5: Hedder Address
A6: 5 | B6: Society Address
A7: 6 | B7: Society Email Id
A8: 7 | B8: Society Telephone or Mobile No.
A9: 8 | B9: Total Unit
B10: A) No. of Flat or Room
B11: B) No. Shop
B12: C) No. Office
B13: D) No. Galas
A14: 9 | B14: No. of Print Blank (EXTRA SR. No.)
A15: 10 | B15: Total Unit

Sheet 02_Common_Member_Master
A1: Sr. No. | B1: Membership No. | C1: Share Certificate No. | D1: No. of Shares | E1: Value of One Share | F1: Value of Shares | G1: Share Certificate Range | I1: Members Name Full | O1: Address Permanent | Q1: Address Residential / Care of
G2: From | H2: To | I2: 1 | J2: 2 | K2: 3 | L2: 4 | M2: 5 | N2: 6 | O2: Flat/Room/Shop/Office/Gala No. | P2: Wing No. | Q2: New Address / As Above

Sheet 03_Form_I
A1: Sr. No. | B1: Date of Admission | C1: Date of Payment of Entrance Fees | D1: Members Name Full | J1: Address Permanent | L1: Address Residential / Care of | M1: Occupation | N1: Age on the Date of Admission | O1: Nominee Name Full | U1: Date of Nomination | V1: Date of Cessation of Membership | W1: Reason for Cessation | X1: Remark | Y1: Date | Z1: Cash Book Folio No. | AA1: Application | AB1: Allotment | AC1: Amount Received | AE1: Total Amount Received | AF1: No. of Shares | AG1: Share Certificate
D2: 1 | E2: 2 | F2: 3 | G2: 4 | H2: 5 | I2: 6 | J2: Flat/Room/Shop/Office/Gala No. | K2: Wing No. | L2: New Address / As Above | O2: 1 | P2: 2 | Q2: 3 | R2: 4 | S2: 5 | T2: 6 | AC2: 1st Call | AD2: 2nd Call | AG2: Share Certificate No. | AH2: From | AI2: To
A3: =IF('02_Common_Member_Master'!A3="","",'02_Common_Member_Master'!A3) | D3: =IF('02_Common_Member_Master'!I3="","",'02_Common_Member_Master'!I3) | E3: =IF('02_Common_Member_Master'!J3="","",'02_Common_Member_Master'!J3) | F3: =IF('02_Common_Member_Master'!K3="","",'02_Common_Member_Master'!K3) | G3: =IF('02_Common_Member_Master'!L3="","",'02_Common_Member_Master'!L3) | H3: =IF('02_Common_Member_Master'!M3="","",'02_Common_Member_Master'!M3) | I3: =IF('02_Common_Member_Master'!N3="","",'02_Common_Member_Master'!N3) | J3: =IF('02_Common_Member_Master'!O3="","",'02_Common_Member_Master'!O3) | K3: =IF('02_Common_Member_Master'!P3="","",'02_Common_Member_Master'!P3) | L3: =IF('02_Common_Member_Master'!Q3="","",'02_Common_Member_Master'!Q3) | AF3: =IF('02_Common_Member_Master'!D3="","",'02_Common_Member_Master'!D3) | AG3: =IF('02_Common_Member_Master'!C3="","",'02_Common_Member_Master'!C3) | AH3: =IF('02_Common_Member_Master'!G3="","",'02_Common_Member_Master'!G3) | AI3: =IF('02_Common_Member_Master'!H3="","",'02_Common_Member_Master'!H3)
A4: =IF('02_Common_Member_Master'!A4="","",'02_Common_Member_Master'!A4) | D4: =IF('02_Common_Member_Master'!I4="","",'02_Common_Member_Master'!I4) | E4: =IF('02_Common_Member_Master'!J4="","",'02_Common_Member_Master'!J4) | F4: =IF('02_Common_Member_Master'!K4="","",'02_Common_Member_Master'!K4) | G4: =IF('02_Common_Member_Master'!L4="","",'02_Common_Member_Master'!L4) | H4: =IF('02_Common_Member_Master'!M4="","",'02_Common_Member_Master'!M4) | I4: =IF('02_Common_Member_Master'!N4="","",'02_Common_Member_Master'!N4) | J4: =IF('02_Common_Member_Master'!O4="","",'02_Common_Member_Master'!O4) | K4: =IF('02_Common_Member_Master'!P4="","",'02_Common_Member_Master'!P4) | L4: =IF('02_Common_Member_Master'!Q4="","",'02_Common_Member_Master'!Q4) | AF4: =IF('02_Common_Member_Master'!D4="","",'02_Common_Member_Master'!D4) | AG4: =IF('02_Common_Member_Master'!C4="","",'02_Common_Member_Master'!C4) | AH4: =IF('02_Common_Member_Master'!G4="","",'02_Common_Member_Master'!G4) | AI4: =IF('02_Common_Member_Master'!H4="","",'02_Common_Member_Master'!H4)
A5: =IF('02_Common_Member_Master'!A5="","",'02_Common_Member_Master'!A5) | D5: =IF('02_Common_Member_Master'!I5="","",'02_Common_Member_Master'!I5) | E5: =IF('02_Common_Member_Master'!J5="","",'02_Common_Member_Master'!J5) | F5: =IF('02_Common_Member_Master'!K5="","",'02_Common_Member_Master'!K5) | G5: =IF('02_Common_Member_Master'!L5="","",'02_Common_Member_Master'!L5) | H5: =IF('02_Common_Member_Master'!M5="","",'02_Common_Member_Master'!M5) | I5: =IF('02_Common_Member_Master'!N5="","",'02_Common_Member_Master'!N5) | J5: =IF('02_Common_Member_Master'!O5="","",'02_Common_Member_Master'!O5) | K5: =IF('02_Common_Member_Master'!P5="","",'02_Common_Member_Master'!P5) | L5: =IF('02_Common_Member_Master'!Q5="","",'02_Common_Member_Master'!Q5) | AF5: =IF('02_Common_Member_Master'!D5="","",'02_Common_Member_Master'!D5) | AG5: =IF('02_Common_Member_Master'!C5="","",'02_Common_Member_Master'!C5) | AH5: =IF('02_Common_Member_Master'!G5="","",'02_Common_Member_Master'!G5) | AI5: =IF('02_Common_Member_Master'!H5="","",'02_Common_Member_Master'!H5)
A6: =IF('02_Common_Member_Master'!A6="","",'02_Common_Member_Master'!A6) | D6: =IF('02_Common_Member_Master'!I6="","",'02_Common_Member_Master'!I6) | E6: =IF('02_Common_Member_Master'!J6="","",'02_Common_Member_Master'!J6) | F6: =IF('02_Common_Member_Master'!K6="","",'02_Common_Member_Master'!K6) | G6: =IF('02_Common_Member_Master'!L6="","",'02_Common_Member_Master'!L6) | H6: =IF('02_Common_Member_Master'!M6="","",'02_Common_Member_Master'!M6) | I6: =IF('02_Common_Member_Master'!N6="","",'02_Common_Member_Master'!N6) | J6: =IF('02_Common_Member_Master'!O6="","",'02_Common_Member_Master'!O6) | K6: =IF('02_Common_Member_Master'!P6="","",'02_Common_Member_Master'!P6) | L6: =IF('02_Common_Member_Master'!Q6="","",'02_Common_Member_Master'!Q6) | AF6: =IF('02_Common_Member_Master'!D6="","",'02_Common_Member_Master'!D6) | AG6: =IF('02_Common_Member_Master'!C6="","",'02_Common_Member_Master'!C6) | AH6: =IF('02_Common_Member_Master'!G6="","",'02_Common_Member_Master'!G6) | AI6: =IF('02_Common_Member_Master'!H6="","",'02_Common_Member_Master'!H6)
A7: =IF('02_Common_Member_Master'!A7="","",'02_Common_Member_Master'!A7) | D7: =IF('02_Common_Member_Master'!I7="","",'02_Common_Member_Master'!I7) | E7: =IF('02_Common_Member_Master'!J7="","",'02_Common_Member_Master'!J7) | F7: =IF('02_Common_Member_Master'!K7="","",'02_Common_Member_Master'!K7) | G7: =IF('02_Common_Member_Master'!L7="","",'02_Common_Member_Master'!L7) | H7: =IF('02_Common_Member_Master'!M7="","",'02_Common_Member_Master'!M7) | I7: =IF('02_Common_Member_Master'!N7="","",'02_Common_Member_Master'!N7) | J7: =IF('02_Common_Member_Master'!O7="","",'02_Common_Member_Master'!O7) | K7: =IF('02_Common_Member_Master'!P7="","",'02_Common_Member_Master'!P7) | L7: =IF('02_Common_Member_Master'!Q7="","",'02_Common_Member_Master'!Q7) | AF7: =IF('02_Common_Member_Master'!D7="","",'02_Common_Member_Master'!D7) | AG7: =IF('02_Common_Member_Master'!C7="","",'02_Common_Member_Master'!C7) | AH7: =IF('02_Common_Member_Master'!G7="","",'02_Common_Member_Master'!G7) | AI7: =IF('02_Common_Member_Master'!H7="","",'02_Common_Member_Master'!H7)
A8: =IF('02_Common_Member_Master'!A8="","",'02_Common_Member_Master'!A8) | D8: =IF('02_Common_Member_Master'!I8="","",'02_Common_Member_Master'!I8) | E8: =IF('02_Common_Member_Master'!J8="","",'02_Common_Member_Master'!J8) | F8: =IF('02_Common_Member_Master'!K8="","",'02_Common_Member_Master'!K8) | G8: =IF('02_Common_Member_Master'!L8="","",'02_Common_Member_Master'!L8) | H8: =IF('02_Common_Member_Master'!M8="","",'02_Common_Member_Master'!M8) | I8: =IF('02_Common_Member_Master'!N8="","",'02_Common_Member_Master'!N8) | J8: =IF('02_Common_Member_Master'!O8="","",'02_Common_Member_Master'!O8) | K8: =IF('02_Common_Member_Master'!P8="","",'02_Common_Member_Master'!P8) | L8: =IF('02_Common_Member_Master'!Q8="","",'02_Common_Member_Master'!Q8) | AF8: =IF('02_Common_Member_Master'!D8="","",'02_Common_Member_Master'!D8) | AG8: =IF('02_Common_Member_Master'!C8="","",'02_Common_Member_Master'!C8) | AH8: =IF('02_Common_Member_Master'!G8="","",'02_Common_Member_Master'!G8) | AI8: =IF('02_Common_Member_Master'!H8="","",'02_Common_Member_Master'!H8)
A9: =IF('02_Common_Member_Master'!A9="","",'02_Common_Member_Master'!A9) | D9: =IF('02_Common_Member_Master'!I9="","",'02_Common_Member_Master'!I9) | E9: =IF('02_Common_Member_Master'!J9="","",'02_Common_Member_Master'!J9) | F9: =IF('02_Common_Member_Master'!K9="","",'02_Common_Member_Master'!K9) | G9: =IF('02_Common_Member_Master'!L9="","",'02_Common_Member_Master'!L9) | H9: =IF('02_Common_Member_Master'!M9="","",'02_Common_Member_Master'!M9) | I9: =IF('02_Common_Member_Master'!N9="","",'02_Common_Member_Master'!N9) | J9: =IF('02_Common_Member_Master'!O9="","",'02_Common_Member_Master'!O9) | K9: =IF('02_Common_Member_Master'!P9="","",'02_Common_Member_Master'!P9) | L9: =IF('02_Common_Member_Master'!Q9="","",'02_Common_Member_Master'!Q9) | AF9: =IF('02_Common_Member_Master'!D9="","",'02_Common_Member_Master'!D9) | AG9: =IF('02_Common_Member_Master'!C9="","",'02_Common_Member_Master'!C9) | AH9: =IF('02_Common_Member_Master'!G9="","",'02_Common_Member_Master'!G9) | AI9: =IF('02_Common_Member_Master'!H9="","",'02_Common_Member_Master'!H9)
A10: =IF('02_Common_Member_Master'!A10="","",'02_Common_Member_Master'!A10) | D10: =IF('02_Common_Member_Master'!I10="","",'02_Common_Member_Master'!I10) | E10: =IF('02_Common_Member_Master'!J10="","",'02_Common_Member_Master'!J10) | F10: =IF('02_Common_Member_Master'!K10="","",'02_Common_Member_Master'!K10) | G10: =IF('02_Common_Member_Master'!L10="","",'02_Common_Member_Master'!L10) | H10: =IF('02_Common_Member_Master'!M10="","",'02_Common_Member_Master'!M10) | I10: =IF('02_Common_Member_Master'!N10="","",'02_Common_Member_Master'!N10) | J10: =IF('02_Common_Member_Master'!O10="","",'02_Common_Member_Master'!O10) | K10: =IF('02_Common_Member_Master'!P10="","",'02_Common_Member_Master'!P10) | L10: =IF('02_Common_Member_Master'!Q10="","",'02_Common_Member_Master'!Q10) | AF10: =IF('02_Common_Member_Master'!D10="","",'02_Common_Member_Master'!D10) | AG10: =IF('02_Common_Member_Master'!C10="","",'02_Common_Member_Master'!C10) | AH10: =IF('02_Common_Member_Master'!G10="","",'02_Common_Member_Master'!G10) | AI10: =IF('02_Common_Member_Master'!H10="","",'02_Common_Member_Master'!H10)
A11: =IF('02_Common_Member_Master'!A11="","",'02_Common_Member_Master'!A11) | D11: =IF('02_Common_Member_Master'!I11="","",'02_Common_Member_Master'!I11) | E11: =IF('02_Common_Member_Master'!J11="","",'02_Common_Member_Master'!J11) | F11: =IF('02_Common_Member_Master'!K11="","",'02_Common_Member_Master'!K11) | G11: =IF('02_Common_Member_Master'!L11="","",'02_Common_Member_Master'!L11) | H11: =IF('02_Common_Member_Master'!M11="","",'02_Common_Member_Master'!M11) | I11: =IF('02_Common_Member_Master'!N11="","",'02_Common_Member_Master'!N11) | J11: =IF('02_Common_Member_Master'!O11="","",'02_Common_Member_Master'!O11) | K11: =IF('02_Common_Member_Master'!P11="","",'02_Common_Member_Master'!P11) | L11: =IF('02_Common_Member_Master'!Q11="","",'02_Common_Member_Master'!Q11) | AF11: =IF('02_Common_Member_Master'!D11="","",'02_Common_Member_Master'!D11) | AG11: =IF('02_Common_Member_Master'!C11="","",'02_Common_Member_Master'!C11) | AH11: =IF('02_Common_Member_Master'!G11="","",'02_Common_Member_Master'!G11) | AI11: =IF('02_Common_Member_Master'!H11="","",'02_Common_Member_Master'!H11)
A12: =IF('02_Common_Member_Master'!A12="","",'02_Common_Member_Master'!A12) | D12: =IF('02_Common_Member_Master'!I12="","",'02_Common_Member_Master'!I12) | E12: =IF('02_Common_Member_Master'!J12="","",'02_Common_Member_Master'!J12) | F12: =IF('02_Common_Member_Master'!K12="","",'02_Common_Member_Master'!K12) | G12: =IF('02_Common_Member_Master'!L12="","",'02_Common_Member_Master'!L12) | H12: =IF('02_Common_Member_Master'!M12="","",'02_Common_Member_Master'!M12) | I12: =IF('02_Common_Member_Master'!N12="","",'02_Common_Member_Master'!N12) | J12: =IF('02_Common_Member_Master'!O12="","",'02_Common_Member_Master'!O12) | K12: =IF('02_Common_Member_Master'!P12="","",'02_Common_Member_Master'!P12) | L12: =IF('02_Common_Member_Master'!Q12="","",'02_Common_Member_Master'!Q12) | AF12: =IF('02_Common_Member_Master'!D12="","",'02_Common_Member_Master'!D12) | AG12: =IF('02_Common_Member_Master'!C12="","",'02_Common_Member_Master'!C12) | AH12: =IF('02_Common_Member_Master'!G12="","",'02_Common_Member_Master'!G12) | AI12: =IF('02_Common_Member_Master'!H12="","",'02_Common_Member_Master'!H12)
A13: =IF('02_Common_Member_Master'!A13="","",'02_Common_Member_Master'!A13) | D13: =IF('02_Common_Member_Master'!I13="","",'02_Common_Member_Master'!I13) | E13: =IF('02_Common_Member_Master'!J13="","",'02_Common_Member_Master'!J13) | F13: =IF('02_Common_Member_Master'!K13="","",'02_Common_Member_Master'!K13) | G13: =IF('02_Common_Member_Master'!L13="","",'02_Common_Member_Master'!L13) | H13: =IF('02_Common_Member_Master'!M13="","",'02_Common_Member_Master'!M13) | I13: =IF('02_Common_Member_Master'!N13="","",'02_Common_Member_Master'!N13) | J13: =IF('02_Common_Member_Master'!O13="","",'02_Common_Member_Master'!O13) | K13: =IF('02_Common_Member_Master'!P13="","",'02_Common_Member_Master'!P13) | L13: =IF('02_Common_Member_Master'!Q13="","",'02_Common_Member_Master'!Q13) | AF13: =IF('02_Common_Member_Master'!D13="","",'02_Common_Member_Master'!D13) | AG13: =IF('02_Common_Member_Master'!C13="","",'02_Common_Member_Master'!C13) | AH13: =IF('02_Common_Member_Master'!G13="","",'02_Common_Member_Master'!G13) | AI13: =IF('02_Common_Member_Master'!H13="","",'02_Common_Member_Master'!H13)
A14: =IF('02_Common_Member_Master'!A14="","",'02_Common_Member_Master'!A14) | D14: =IF('02_Common_Member_Master'!I14="","",'02_Common_Member_Master'!I14) | E14: =IF('02_Common_Member_Master'!J14="","",'02_Common_Member_Master'!J14) | F14: =IF('02_Common_Member_Master'!K14="","",'02_Common_Member_Master'!K14) | G14: =IF('02_Common_Member_Master'!L14="","",'02_Common_Member_Master'!L14) | H14: =IF('02_Common_Member_Master'!M14="","",'02_Common_Member_Master'!M14) | I14: =IF('02_Common_Member_Master'!N14="","",'02_Common_Member_Master'!N14) | J14: =IF('02_Common_Member_Master'!O14="","",'02_Common_Member_Master'!O14) | K14: =IF('02_Common_Member_Master'!P14="","",'02_Common_Member_Master'!P14) | L14: =IF('02_Common_Member_Master'!Q14="","",'02_Common_Member_Master'!Q14) | AF14: =IF('02_Common_Member_Master'!D14="","",'02_Common_Member_Master'!D14) | AG14: =IF('02_Common_Member_Master'!C14="","",'02_Common_Member_Master'!C14) | AH14: =IF('02_Common_Member_Master'!G14="","",'02_Common_Member_Master'!G14) | AI14: =IF('02_Common_Member_Master'!H14="","",'02_Common_Member_Master'!H14)
... A23: =IF('02_Common_Member_Master'!A23="","",'02_Common_Member_Master'!A23) | D23: =IF('02_Common_Member_Master'!I23="","",'02_Common_Member_Master'!I23) | E23: =IF('02_Common_Member_Master'!J23="","",'02_Common_Member_Master'!J23) | F23: =IF('02_Common_Member_Master'!K23="","",'02_Common_Member_Master'!K23) | G23: =IF('02_Common_Member_Master'!L23="","",'02_Common_Member_Master'!L23) | H23: =IF('02_Common_Member_Master'!M23="","",'02_Common_Member_Master'!M23) | I23: =IF('02_Common_Member_Master'!N23="","",'02_Common_Member_Master'!N23) | J23: =IF('02_Common_Member_Master'!O23="","",'02_Common_Member_Master'!O23) | K23: =IF('02_Common_Member_Master'!P23="","",'02_Common_Member_Master'!P23) | L23: =IF('02_Common_Member_Master'!Q23="","",'02_Common_Member_Master'!Q23) | AF23: =IF('02_Common_Member_Master'!D23="","",'02_Common_Member_Master'!D23) | AG23: =IF('02_Common_Member_Master'!C23="","",'02_Common_Member_Master'!C23) | AH23: =IF('02_Common_Member_Master'!G23="","",'02_Common_Member_Master'!G23) | AI23: =IF('02_Common_Member_Master'!H23="","",'02_Common_Member_Master'!H23)

Sheet 04_Form_J
A1: Sr. No. | B1: Members Name Full | H1: Permanent Address | J1: Class of Member
B2: 1 | C2: 2 | D2: 3 | E2: 4 | F2: 5 | G2: 6 | H2: Flat/Room/Shop/Office/Gala No. | I2: Wing No.
A3: =IF('02_Common_Member_Master'!A3="","",'02_Common_Member_Master'!A3) | B3: =IF('02_Common_Member_Master'!I3="","",'02_Common_Member_Master'!I3) | C3: =IF('02_Common_Member_Master'!J3="","",'02_Common_Member_Master'!J3) | D3: =IF('02_Common_Member_Master'!K3="","",'02_Common_Member_Master'!K3) | E3: =IF('02_Common_Member_Master'!L3="","",'02_Common_Member_Master'!L3) | F3: =IF('02_Common_Member_Master'!M3="","",'02_Common_Member_Master'!M3) | G3: =IF('02_Common_Member_Master'!N3="","",'02_Common_Member_Master'!N3) | H3: =IF('02_Common_Member_Master'!O3="","",'02_Common_Member_Master'!O3) | I3: =IF('02_Common_Member_Master'!P3="","",'02_Common_Member_Master'!P3)
A4: =IF('02_Common_Member_Master'!A4="","",'02_Common_Member_Master'!A4) | B4: =IF('02_Common_Member_Master'!I4="","",'02_Common_Member_Master'!I4) | C4: =IF('02_Common_Member_Master'!J4="","",'02_Common_Member_Master'!J4) | D4: =IF('02_Common_Member_Master'!K4="","",'02_Common_Member_Master'!K4) | E4: =IF('02_Common_Member_Master'!L4="","",'02_Common_Member_Master'!L4) | F4: =IF('02_Common_Member_Master'!M4="","",'02_Common_Member_Master'!M4) | G4: =IF('02_Common_Member_Master'!N4="","",'02_Common_Member_Master'!N4) | H4: =IF('02_Common_Member_Master'!O4="","",'02_Common_Member_Master'!O4) | I4: =IF('02_Common_Member_Master'!P4="","",'02_Common_Member_Master'!P4)
A5: =IF('02_Common_Member_Master'!A5="","",'02_Common_Member_Master'!A5) | B5: =IF('02_Common_Member_Master'!I5="","",'02_Common_Member_Master'!I5) | C5: =IF('02_Common_Member_Master'!J5="","",'02_Common_Member_Master'!J5) | D5: =IF('02_Common_Member_Master'!K5="","",'02_Common_Member_Master'!K5) | E5: =IF('02_Common_Member_Master'!L5="","",'02_Common_Member_Master'!L5) | F5: =IF('02_Common_Member_Master'!M5="","",'02_Common_Member_Master'!M5) | G5: =IF('02_Common_Member_Master'!N5="","",'02_Common_Member_Master'!N5) | H5: =IF('02_Common_Member_Master'!O5="","",'02_Common_Member_Master'!O5) | I5: =IF('02_Common_Member_Master'!P5="","",'02_Common_Member_Master'!P5)
A6: =IF('02_Common_Member_Master'!A6="","",'02_Common_Member_Master'!A6) | B6: =IF('02_Common_Member_Master'!I6="","",'02_Common_Member_Master'!I6) | C6: =IF('02_Common_Member_Master'!J6="","",'02_Common_Member_Master'!J6) | D6: =IF('02_Common_Member_Master'!K6="","",'02_Common_Member_Master'!K6) | E6: =IF('02_Common_Member_Master'!L6="","",'02_Common_Member_Master'!L6) | F6: =IF('02_Common_Member_Master'!M6="","",'02_Common_Member_Master'!M6) | G6: =IF('02_Common_Member_Master'!N6="","",'02_Common_Member_Master'!N6) | H6: =IF('02_Common_Member_Master'!O6="","",'02_Common_Member_Master'!O6) | I6: =IF('02_Common_Member_Master'!P6="","",'02_Common_Member_Master'!P6)
A7: =IF('02_Common_Member_Master'!A7="","",'02_Common_Member_Master'!A7) | B7: =IF('02_Common_Member_Master'!I7="","",'02_Common_Member_Master'!I7) | C7: =IF('02_Common_Member_Master'!J7="","",'02_Common_Member_Master'!J7) | D7: =IF('02_Common_Member_Master'!K7="","",'02_Common_Member_Master'!K7) | E7: =IF('02_Common_Member_Master'!L7="","",'02_Common_Member_Master'!L7) | F7: =IF('02_Common_Member_Master'!M7="","",'02_Common_Member_Master'!M7) | G7: =IF('02_Common_Member_Master'!N7="","",'02_Common_Member_Master'!N7) | H7: =IF('02_Common_Member_Master'!O7="","",'02_Common_Member_Master'!O7) | I7: =IF('02_Common_Member_Master'!P7="","",'02_Common_Member_Master'!P7)
A8: =IF('02_Common_Member_Master'!A8="","",'02_Common_Member_Master'!A8) | B8: =IF('02_Common_Member_Master'!I8="","",'02_Common_Member_Master'!I8) | C8: =IF('02_Common_Member_Master'!J8="","",'02_Common_Member_Master'!J8) | D8: =IF('02_Common_Member_Master'!K8="","",'02_Common_Member_Master'!K8) | E8: =IF('02_Common_Member_Master'!L8="","",'02_Common_Member_Master'!L8) | F8: =IF('02_Common_Member_Master'!M8="","",'02_Common_Member_Master'!M8) | G8: =IF('02_Common_Member_Master'!N8="","",'02_Common_Member_Master'!N8) | H8: =IF('02_Common_Member_Master'!O8="","",'02_Common_Member_Master'!O8) | I8: =IF('02_Common_Member_Master'!P8="","",'02_Common_Member_Master'!P8)
A9: =IF('02_Common_Member_Master'!A9="","",'02_Common_Member_Master'!A9) | B9: =IF('02_Common_Member_Master'!I9="","",'02_Common_Member_Master'!I9) | C9: =IF('02_Common_Member_Master'!J9="","",'02_Common_Member_Master'!J9) | D9: =IF('02_Common_Member_Master'!K9="","",'02_Common_Member_Master'!K9) | E9: =IF('02_Common_Member_Master'!L9="","",'02_Common_Member_Master'!L9) | F9: =IF('02_Common_Member_Master'!M9="","",'02_Common_Member_Master'!M9) | G9: =IF('02_Common_Member_Master'!N9="","",'02_Common_Member_Master'!N9) | H9: =IF('02_Common_Member_Master'!O9="","",'02_Common_Member_Master'!O9) | I9: =IF('02_Common_Member_Master'!P9="","",'02_Common_Member_Master'!P9)
A10: =IF('02_Common_Member_Master'!A10="","",'02_Common_Member_Master'!A10) | B10: =IF('02_Common_Member_Master'!I10="","",'02_Common_Member_Master'!I10) | C10: =IF('02_Common_Member_Master'!J10="","",'02_Common_Member_Master'!J10) | D10: =IF('02_Common_Member_Master'!K10="","",'02_Common_Member_Master'!K10) | E10: =IF('02_Common_Member_Master'!L10="","",'02_Common_Member_Master'!L10) | F10: =IF('02_Common_Member_Master'!M10="","",'02_Common_Member_Master'!M10) | G10: =IF('02_Common_Member_Master'!N10="","",'02_Common_Member_Master'!N10) | H10: =IF('02_Common_Member_Master'!O10="","",'02_Common_Member_Master'!O10) | I10: =IF('02_Common_Member_Master'!P10="","",'02_Common_Member_Master'!P10)
A11: =IF('02_Common_Member_Master'!A11="","",'02_Common_Member_Master'!A11) | B11: =IF('02_Common_Member_Master'!I11="","",'02_Common_Member_Master'!I11) | C11: =IF('02_Common_Member_Master'!J11="","",'02_Common_Member_Master'!J11) | D11: =IF('02_Common_Member_Master'!K11="","",'02_Common_Member_Master'!K11) | E11: =IF('02_Common_Member_Master'!L11="","",'02_Common_Member_Master'!L11) | F11: =IF('02_Common_Member_Master'!M11="","",'02_Common_Member_Master'!M11) | G11: =IF('02_Common_Member_Master'!N11="","",'02_Common_Member_Master'!N11) | H11: =IF('02_Common_Member_Master'!O11="","",'02_Common_Member_Master'!O11) | I11: =IF('02_Common_Member_Master'!P11="","",'02_Common_Member_Master'!P11)
A12: =IF('02_Common_Member_Master'!A12="","",'02_Common_Member_Master'!A12) | B12: =IF('02_Common_Member_Master'!I12="","",'02_Common_Member_Master'!I12) | C12: =IF('02_Common_Member_Master'!J12="","",'02_Common_Member_Master'!J12) | D12: =IF('02_Common_Member_Master'!K12="","",'02_Common_Member_Master'!K12) | E12: =IF('02_Common_Member_Master'!L12="","",'02_Common_Member_Master'!L12) | F12: =IF('02_Common_Member_Master'!M12="","",'02_Common_Member_Master'!M12) | G12: =IF('02_Common_Member_Master'!N12="","",'02_Common_Member_Master'!N12) | H12: =IF('02_Common_Member_Master'!O12="","",'02_Common_Member_Master'!O12) | I12: =IF('02_Common_Member_Master'!P12="","",'02_Common_Member_Master'!P12)
A13: =IF('02_Common_Member_Master'!A13="","",'02_Common_Member_Master'!A13) | B13: =IF('02_Common_Member_Master'!I13="","",'02_Common_Member_Master'!I13) | C13: =IF('02_Common_Member_Master'!J13="","",'02_Common_Member_Master'!J13) | D13: =IF('02_Common_Member_Master'!K13="","",'02_Common_Member_Master'!K13) | E13: =IF('02_Common_Member_Master'!L13="","",'02_Common_Member_Master'!L13) | F13: =IF('02_Common_Member_Master'!M13="","",'02_Common_Member_Master'!M13) | G13: =IF('02_Common_Member_Master'!N13="","",'02_Common_Member_Master'!N13) | H13: =IF('02_Common_Member_Master'!O13="","",'02_Common_Member_Master'!O13) | I13: =IF('02_Common_Member_Master'!P13="","",'02_Common_Member_Master'!P13)
A14: =IF('02_Common_Member_Master'!A14="","",'02_Common_Member_Master'!A14) | B14: =IF('02_Common_Member_Master'!I14="","",'02_Common_Member_Master'!I14) | C14: =IF('02_Common_Member_Master'!J14="","",'02_Common_Member_Master'!J14) | D14: =IF('02_Common_Member_Master'!K14="","",'02_Common_Member_Master'!K14) | E14: =IF('02_Common_Member_Master'!L14="","",'02_Common_Member_Master'!L14) | F14: =IF('02_Common_Member_Master'!M14="","",'02_Common_Member_Master'!M14) | G14: =IF('02_Common_Member_Master'!N14="","",'02_Common_Member_Master'!N14) | H14: =IF('02_Common_Member_Master'!O14="","",'02_Common_Member_Master'!O14) | I14: =IF('02_Common_Member_Master'!P14="","",'02_Common_Member_Master'!P14)
... A23: =IF('02_Common_Member_Master'!A23="","",'02_Common_Member_Master'!A23) | B23: =IF('02_Common_Member_Master'!I23="","",'02_Common_Member_Master'!I23) | C23: =IF('02_Common_Member_Master'!J23="","",'02_Common_Member_Master'!J23) | D23: =IF('02_Common_Member_Master'!K23="","",'02_Common_Member_Master'!K23) | E23: =IF('02_Common_Member_Master'!L23="","",'02_Common_Member_Master'!L23) | F23: =IF('02_Common_Member_Master'!M23="","",'02_Common_Member_Master'!M23) | G23: =IF('02_Common_Member_Master'!N23="","",'02_Common_Member_Master'!N23) | H23: =IF('02_Common_Member_Master'!O23="","",'02_Common_Member_Master'!O23) | I23: =IF('02_Common_Member_Master'!P23="","",'02_Common_Member_Master'!P23)

Sheet 05_Share_Register
A1: Sr. No. | B1: Date of allotment of Share | C1: Cash Book folio No. | D1: Share Certificate No. | E1: No. of Shares | F1: Value of One Share | G1: Value of Shares | H1: Address | J1: Members Name Full | P1: Details of Shares Transferred or Refunded
H2: Flat/Room/Shop/Office/Gala No. | I2: Wing No. | J2: 1 | K2: 2 | L2: 3 | M2: 4 | N2: 5 | O2: 6 | P2: Date of transfer / refund | Q2: Cash Book Journal Folio No. | R2: No. of Shares Transferred/Refunded From | S2: No. of Shares Transferred/Refunded To | T2: Share Certificate No. transferred or refunded | U2: Share Value transferred or refunded Rs. | V2: Name of the transferee or person receiving refund | W2: Authority for transfer or refund | X2: Remark
A3: =IF('02_Common_Member_Master'!A3="","",'02_Common_Member_Master'!A3) | D3: =IF('02_Common_Member_Master'!C3="","",'02_Common_Member_Master'!C3) | E3: =IF('02_Common_Member_Master'!D3="","",'02_Common_Member_Master'!D3) | F3: =IF('02_Common_Member_Master'!E3="","",'02_Common_Member_Master'!E3) | G3: =IF('02_Common_Member_Master'!F3="","",'02_Common_Member_Master'!F3) | H3: =IF('02_Common_Member_Master'!O3="","",'02_Common_Member_Master'!O3) | I3: =IF('02_Common_Member_Master'!P3="","",'02_Common_Member_Master'!P3) | J3: =IF('02_Common_Member_Master'!I3="","",'02_Common_Member_Master'!I3) | K3: =IF('02_Common_Member_Master'!J3="","",'02_Common_Member_Master'!J3) | L3: =IF('02_Common_Member_Master'!K3="","",'02_Common_Member_Master'!K3) | M3: =IF('02_Common_Member_Master'!L3="","",'02_Common_Member_Master'!L3) | N3: =IF('02_Common_Member_Master'!M3="","",'02_Common_Member_Master'!M3) | O3: =IF('02_Common_Member_Master'!N3="","",'02_Common_Member_Master'!N3)
A4: =IF('02_Common_Member_Master'!A4="","",'02_Common_Member_Master'!A4) | D4: =IF('02_Common_Member_Master'!C4="","",'02_Common_Member_Master'!C4) | E4: =IF('02_Common_Member_Master'!D4="","",'02_Common_Member_Master'!D4) | F4: =IF('02_Common_Member_Master'!E4="","",'02_Common_Member_Master'!E4) | G4: =IF('02_Common_Member_Master'!F4="","",'02_Common_Member_Master'!F4) | H4: =IF('02_Common_Member_Master'!O4="","",'02_Common_Member_Master'!O4) | I4: =IF('02_Common_Member_Master'!P4="","",'02_Common_Member_Master'!P4) | J4: =IF('02_Common_Member_Master'!I4="","",'02_Common_Member_Master'!I4) | K4: =IF('02_Common_Member_Master'!J4="","",'02_Common_Member_Master'!J4) | L4: =IF('02_Common_Member_Master'!K4="","",'02_Common_Member_Master'!K4) | M4: =IF('02_Common_Member_Master'!L4="","",'02_Common_Member_Master'!L4) | N4: =IF('02_Common_Member_Master'!M4="","",'02_Common_Member_Master'!M4) | O4: =IF('02_Common_Member_Master'!N4="","",'02_Common_Member_Master'!N4)
A5: =IF('02_Common_Member_Master'!A5="","",'02_Common_Member_Master'!A5) | D5: =IF('02_Common_Member_Master'!C5="","",'02_Common_Member_Master'!C5) | E5: =IF('02_Common_Member_Master'!D5="","",'02_Common_Member_Master'!D5) | F5: =IF('02_Common_Member_Master'!E5="","",'02_Common_Member_Master'!E5) | G5: =IF('02_Common_Member_Master'!F5="","",'02_Common_Member_Master'!F5) | H5: =IF('02_Common_Member_Master'!O5="","",'02_Common_Member_Master'!O5) | I5: =IF('02_Common_Member_Master'!P5="","",'02_Common_Member_Master'!P5) | J5: =IF('02_Common_Member_Master'!I5="","",'02_Common_Member_Master'!I5) | K5: =IF('02_Common_Member_Master'!J5="","",'02_Common_Member_Master'!J5) | L5: =IF('02_Common_Member_Master'!K5="","",'02_Common_Member_Master'!K5) | M5: =IF('02_Common_Member_Master'!L5="","",'02_Common_Member_Master'!L5) | N5: =IF('02_Common_Member_Master'!M5="","",'02_Common_Member_Master'!M5) | O5: =IF('02_Common_Member_Master'!N5="","",'02_Common_Member_Master'!N5)
A6: =IF('02_Common_Member_Master'!A6="","",'02_Common_Member_Master'!A6) | D6: =IF('02_Common_Member_Master'!C6="","",'02_Common_Member_Master'!C6) | E6: =IF('02_Common_Member_Master'!D6="","",'02_Common_Member_Master'!D6) | F6: =IF('02_Common_Member_Master'!E6="","",'02_Common_Member_Master'!E6) | G6: =IF('02_Common_Member_Master'!F6="","",'02_Common_Member_Master'!F6) | H6: =IF('02_Common_Member_Master'!O6="","",'02_Common_Member_Master'!O6) | I6: =IF('02_Common_Member_Master'!P6="","",'02_Common_Member_Master'!P6) | J6: =IF('02_Common_Member_Master'!I6="","",'02_Common_Member_Master'!I6) | K6: =IF('02_Common_Member_Master'!J6="","",'02_Common_Member_Master'!J6) | L6: =IF('02_Common_Member_Master'!K6="","",'02_Common_Member_Master'!K6) | M6: =IF('02_Common_Member_Master'!L6="","",'02_Common_Member_Master'!L6) | N6: =IF('02_Common_Member_Master'!M6="","",'02_Common_Member_Master'!M6) | O6: =IF('02_Common_Member_Master'!N6="","",'02_Common_Member_Master'!N6)
A7: =IF('02_Common_Member_Master'!A7="","",'02_Common_Member_Master'!A7) | D7: =IF('02_Common_Member_Master'!C7="","",'02_Common_Member_Master'!C7) | E7: =IF('02_Common_Member_Master'!D7="","",'02_Common_Member_Master'!D7) | F7: =IF('02_Common_Member_Master'!E7="","",'02_Common_Member_Master'!E7) | G7: =IF('02_Common_Member_Master'!F7="","",'02_Common_Member_Master'!F7) | H7: =IF('02_Common_Member_Master'!O7="","",'02_Common_Member_Master'!O7) | I7: =IF('02_Common_Member_Master'!P7="","",'02_Common_Member_Master'!P7) | J7: =IF('02_Common_Member_Master'!I7="","",'02_Common_Member_Master'!I7) | K7: =IF('02_Common_Member_Master'!J7="","",'02_Common_Member_Master'!J7) | L7: =IF('02_Common_Member_Master'!K7="","",'02_Common_Member_Master'!K7) | M7: =IF('02_Common_Member_Master'!L7="","",'02_Common_Member_Master'!L7) | N7: =IF('02_Common_Member_Master'!M7="","",'02_Common_Member_Master'!M7) | O7: =IF('02_Common_Member_Master'!N7="","",'02_Common_Member_Master'!N7)
A8: =IF('02_Common_Member_Master'!A8="","",'02_Common_Member_Master'!A8) | D8: =IF('02_Common_Member_Master'!C8="","",'02_Common_Member_Master'!C8) | E8: =IF('02_Common_Member_Master'!D8="","",'02_Common_Member_Master'!D8) | F8: =IF('02_Common_Member_Master'!E8="","",'02_Common_Member_Master'!E8) | G8: =IF('02_Common_Member_Master'!F8="","",'02_Common_Member_Master'!F8) | H8: =IF('02_Common_Member_Master'!O8="","",'02_Common_Member_Master'!O8) | I8: =IF('02_Common_Member_Master'!P8="","",'02_Common_Member_Master'!P8) | J8: =IF('02_Common_Member_Master'!I8="","",'02_Common_Member_Master'!I8) | K8: =IF('02_Common_Member_Master'!J8="","",'02_Common_Member_Master'!J8) | L8: =IF('02_Common_Member_Master'!K8="","",'02_Common_Member_Master'!K8) | M8: =IF('02_Common_Member_Master'!L8="","",'02_Common_Member_Master'!L8) | N8: =IF('02_Common_Member_Master'!M8="","",'02_Common_Member_Master'!M8) | O8: =IF('02_Common_Member_Master'!N8="","",'02_Common_Member_Master'!N8)
A9: =IF('02_Common_Member_Master'!A9="","",'02_Common_Member_Master'!A9) | D9: =IF('02_Common_Member_Master'!C9="","",'02_Common_Member_Master'!C9) | E9: =IF('02_Common_Member_Master'!D9="","",'02_Common_Member_Master'!D9) | F9: =IF('02_Common_Member_Master'!E9="","",'02_Common_Member_Master'!E9) | G9: =IF('02_Common_Member_Master'!F9="","",'02_Common_Member_Master'!F9) | H9: =IF('02_Common_Member_Master'!O9="","",'02_Common_Member_Master'!O9) | I9: =IF('02_Common_Member_Master'!P9="","",'02_Common_Member_Master'!P9) | J9: =IF('02_Common_Member_Master'!I9="","",'02_Common_Member_Master'!I9) | K9: =IF('02_Common_Member_Master'!J9="","",'02_Common_Member_Master'!J9) | L9: =IF('02_Common_Member_Master'!K9="","",'02_Common_Member_Master'!K9) | M9: =IF('02_Common_Member_Master'!L9="","",'02_Common_Member_Master'!L9) | N9: =IF('02_Common_Member_Master'!M9="","",'02_Common_Member_Master'!M9) | O9: =IF('02_Common_Member_Master'!N9="","",'02_Common_Member_Master'!N9)
A10: =IF('02_Common_Member_Master'!A10="","",'02_Common_Member_Master'!A10) | D10: =IF('02_Common_Member_Master'!C10="","",'02_Common_Member_Master'!C10) | E10: =IF('02_Common_Member_Master'!D10="","",'02_Common_Member_Master'!D10) | F10: =IF('02_Common_Member_Master'!E10="","",'02_Common_Member_Master'!E10) | G10: =IF('02_Common_Member_Master'!F10="","",'02_Common_Member_Master'!F10) | H10: =IF('02_Common_Member_Master'!O10="","",'02_Common_Member_Master'!O10) | I10: =IF('02_Common_Member_Master'!P10="","",'02_Common_Member_Master'!P10) | J10: =IF('02_Common_Member_Master'!I10="","",'02_Common_Member_Master'!I10) | K10: =IF('02_Common_Member_Master'!J10="","",'02_Common_Member_Master'!J10) | L10: =IF('02_Common_Member_Master'!K10="","",'02_Common_Member_Master'!K10) | M10: =IF('02_Common_Member_Master'!L10="","",'02_Common_Member_Master'!L10) | N10: =IF('02_Common_Member_Master'!M10="","",'02_Common_Member_Master'!M10) | O10: =IF('02_Common_Member_Master'!N10="","",'02_Common_Member_Master'!N10)
A11: =IF('02_Common_Member_Master'!A11="","",'02_Common_Member_Master'!A11) | D11: =IF('02_Common_Member_Master'!C11="","",'02_Common_Member_Master'!C11) | E11: =IF('02_Common_Member_Master'!D11="","",'02_Common_Member_Master'!D11) | F11: =IF('02_Common_Member_Master'!E11="","",'02_Common_Member_Master'!E11) | G11: =IF('02_Common_Member_Master'!F11="","",'02_Common_Member_Master'!F11) | H11: =IF('02_Common_Member_Master'!O11="","",'02_Common_Member_Master'!O11) | I11: =IF('02_Common_Member_Master'!P11="","",'02_Common_Member_Master'!P11) | J11: =IF('02_Common_Member_Master'!I11="","",'02_Common_Member_Master'!I11) | K11: =IF('02_Common_Member_Master'!J11="","",'02_Common_Member_Master'!J11) | L11: =IF('02_Common_Member_Master'!K11="","",'02_Common_Member_Master'!K11) | M11: =IF('02_Common_Member_Master'!L11="","",'02_Common_Member_Master'!L11) | N11: =IF('02_Common_Member_Master'!M11="","",'02_Common_Member_Master'!M11) | O11: =IF('02_Common_Member_Master'!N11="","",'02_Common_Member_Master'!N11)
A12: =IF('02_Common_Member_Master'!A12="","",'02_Common_Member_Master'!A12) | D12: =IF('02_Common_Member_Master'!C12="","",'02_Common_Member_Master'!C12) | E12: =IF('02_Common_Member_Master'!D12="","",'02_Common_Member_Master'!D12) | F12: =IF('02_Common_Member_Master'!E12="","",'02_Common_Member_Master'!E12) | G12: =IF('02_Common_Member_Master'!F12="","",'02_Common_Member_Master'!F12) | H12: =IF('02_Common_Member_Master'!O12="","",'02_Common_Member_Master'!O12) | I12: =IF('02_Common_Member_Master'!P12="","",'02_Common_Member_Master'!P12) | J12: =IF('02_Common_Member_Master'!I12="","",'02_Common_Member_Master'!I12) | K12: =IF('02_Common_Member_Master'!J12="","",'02_Common_Member_Master'!J12) | L12: =IF('02_Common_Member_Master'!K12="","",'02_Common_Member_Master'!K12) | M12: =IF('02_Common_Member_Master'!L12="","",'02_Common_Member_Master'!L12) | N12: =IF('02_Common_Member_Master'!M12="","",'02_Common_Member_Master'!M12) | O12: =IF('02_Common_Member_Master'!N12="","",'02_Common_Member_Master'!N12)
A13: =IF('02_Common_Member_Master'!A13="","",'02_Common_Member_Master'!A13) | D13: =IF('02_Common_Member_Master'!C13="","",'02_Common_Member_Master'!C13) | E13: =IF('02_Common_Member_Master'!D13="","",'02_Common_Member_Master'!D13) | F13: =IF('02_Common_Member_Master'!E13="","",'02_Common_Member_Master'!E13) | G13: =IF('02_Common_Member_Master'!F13="","",'02_Common_Member_Master'!F13) | H13: =IF('02_Common_Member_Master'!O13="","",'02_Common_Member_Master'!O13) | I13: =IF('02_Common_Member_Master'!P13="","",'02_Common_Member_Master'!P13) | J13: =IF('02_Common_Member_Master'!I13="","",'02_Common_Member_Master'!I13) | K13: =IF('02_Common_Member_Master'!J13="","",'02_Common_Member_Master'!J13) | L13: =IF('02_Common_Member_Master'!K13="","",'02_Common_Member_Master'!K13) | M13: =IF('02_Common_Member_Master'!L13="","",'02_Common_Member_Master'!L13) | N13: =IF('02_Common_Member_Master'!M13="","",'02_Common_Member_Master'!M13) | O13: =IF('02_Common_Member_Master'!N13="","",'02_Common_Member_Master'!N13)
A14: =IF('02_Common_Member_Master'!A14="","",'02_Common_Member_Master'!A14) | D14: =IF('02_Common_Member_Master'!C14="","",'02_Common_Member_Master'!C14) | E14: =IF('02_Common_Member_Master'!D14="","",'02_Common_Member_Master'!D14) | F14: =IF('02_Common_Member_Master'!E14="","",'02_Common_Member_Master'!E14) | G14: =IF('02_Common_Member_Master'!F14="","",'02_Common_Member_Master'!F14) | H14: =IF('02_Common_Member_Master'!O14="","",'02_Common_Member_Master'!O14) | I14: =IF('02_Common_Member_Master'!P14="","",'02_Common_Member_Master'!P14) | J14: =IF('02_Common_Member_Master'!I14="","",'02_Common_Member_Master'!I14) | K14: =IF('02_Common_Member_Master'!J14="","",'02_Common_Member_Master'!J14) | L14: =IF('02_Common_Member_Master'!K14="","",'02_Common_Member_Master'!K14) | M14: =IF('02_Common_Member_Master'!L14="","",'02_Common_Member_Master'!L14) | N14: =IF('02_Common_Member_Master'!M14="","",'02_Common_Member_Master'!M14) | O14: =IF('02_Common_Member_Master'!N14="","",'02_Common_Member_Master'!N14)
... A23: =IF('02_Common_Member_Master'!A23="","",'02_Common_Member_Master'!A23) | D23: =IF('02_Common_Member_Master'!C23="","",'02_Common_Member_Master'!C23) | E23: =IF('02_Common_Member_Master'!D23="","",'02_Common_Member_Master'!D23) | F23: =IF('02_Common_Member_Master'!E23="","",'02_Common_Member_Master'!E23) | G23: =IF('02_Common_Member_Master'!F23="","",'02_Common_Member_Master'!F23) | H23: =IF('02_Common_Member_Master'!O23="","",'02_Common_Member_Master'!O23) | I23: =IF('02_Common_Member_Master'!P23="","",'02_Common_Member_Master'!P23) | J23: =IF('02_Common_Member_Master'!I23="","",'02_Common_Member_Master'!I23) | K23: =IF('02_Common_Member_Master'!J23="","",'02_Common_Member_Master'!J23) | L23: =IF('02_Common_Member_Master'!K23="","",'02_Common_Member_Master'!K23) | M23: =IF('02_Common_Member_Master'!L23="","",'02_Common_Member_Master'!L23) | N23: =IF('02_Common_Member_Master'!M23="","",'02_Common_Member_Master'!M23) | O23: =IF('02_Common_Member_Master'!N23="","",'02_Common_Member_Master'!N23)

Sheet 06_Nomination_Register
A1: Sr. No. | B1: Member Name | H1: Flat / Wing | J1: Date of Nomination | K1: Name/s of Nominee/s & Addresses of the Nominee/s | Q1: Percentage % | W1: Managing Committee Meeting Date | X1: Revocation Date | Y1: Remarks
B2: 1 | C2: 2 | D2: 3 | E2: 4 | F2: 5 | G2: 6 | H2: Flat No. | I2: Wing No. | K2: 1 | L2: 2 | M2: 3 | N2: 4 | O2: 5 | P2: 6 | Q2: 1 | R2: 2 | S2: 3 | T2: 4 | U2: 5 | V2: 6
A3: =IF('02_Common_Member_Master'!A3="","",'02_Common_Member_Master'!A3) | B3: =IF('02_Common_Member_Master'!I3="","",'02_Common_Member_Master'!I3) | C3: =IF('02_Common_Member_Master'!J3="","",'02_Common_Member_Master'!J3) | D3: =IF('02_Common_Member_Master'!K3="","",'02_Common_Member_Master'!K3) | E3: =IF('02_Common_Member_Master'!L3="","",'02_Common_Member_Master'!L3) | F3: =IF('02_Common_Member_Master'!M3="","",'02_Common_Member_Master'!M3) | G3: =IF('02_Common_Member_Master'!N3="","",'02_Common_Member_Master'!N3) | H3: =IF('02_Common_Member_Master'!O3="","",'02_Common_Member_Master'!O3) | I3: =IF('02_Common_Member_Master'!P3="","",'02_Common_Member_Master'!P3)
A4: =IF('02_Common_Member_Master'!A4="","",'02_Common_Member_Master'!A4) | B4: =IF('02_Common_Member_Master'!I4="","",'02_Common_Member_Master'!I4) | C4: =IF('02_Common_Member_Master'!J4="","",'02_Common_Member_Master'!J4) | D4: =IF('02_Common_Member_Master'!K4="","",'02_Common_Member_Master'!K4) | E4: =IF('02_Common_Member_Master'!L4="","",'02_Common_Member_Master'!L4) | F4: =IF('02_Common_Member_Master'!M4="","",'02_Common_Member_Master'!M4) | G4: =IF('02_Common_Member_Master'!N4="","",'02_Common_Member_Master'!N4) | H4: =IF('02_Common_Member_Master'!O4="","",'02_Common_Member_Master'!O4) | I4: =IF('02_Common_Member_Master'!P4="","",'02_Common_Member_Master'!P4)
A5: =IF('02_Common_Member_Master'!A5="","",'02_Common_Member_Master'!A5) | B5: =IF('02_Common_Member_Master'!I5="","",'02_Common_Member_Master'!I5) | C5: =IF('02_Common_Member_Master'!J5="","",'02_Common_Member_Master'!J5) | D5: =IF('02_Common_Member_Master'!K5="","",'02_Common_Member_Master'!K5) | E5: =IF('02_Common_Member_Master'!L5="","",'02_Common_Member_Master'!L5) | F5: =IF('02_Common_Member_Master'!M5="","",'02_Common_Member_Master'!M5) | G5: =IF('02_Common_Member_Master'!N5="","",'02_Common_Member_Master'!N5) | H5: =IF('02_Common_Member_Master'!O5="","",'02_Common_Member_Master'!O5) | I5: =IF('02_Common_Member_Master'!P5="","",'02_Common_Member_Master'!P5)
A6: =IF('02_Common_Member_Master'!A6="","",'02_Common_Member_Master'!A6) | B6: =IF('02_Common_Member_Master'!I6="","",'02_Common_Member_Master'!I6) | C6: =IF('02_Common_Member_Master'!J6="","",'02_Common_Member_Master'!J6) | D6: =IF('02_Common_Member_Master'!K6="","",'02_Common_Member_Master'!K6) | E6: =IF('02_Common_Member_Master'!L6="","",'02_Common_Member_Master'!L6) | F6: =IF('02_Common_Member_Master'!M6="","",'02_Common_Member_Master'!M6) | G6: =IF('02_Common_Member_Master'!N6="","",'02_Common_Member_Master'!N6) | H6: =IF('02_Common_Member_Master'!O6="","",'02_Common_Member_Master'!O6) | I6: =IF('02_Common_Member_Master'!P6="","",'02_Common_Member_Master'!P6)
A7: =IF('02_Common_Member_Master'!A7="","",'02_Common_Member_Master'!A7) | B7: =IF('02_Common_Member_Master'!I7="","",'02_Common_Member_Master'!I7) | C7: =IF('02_Common_Member_Master'!J7="","",'02_Common_Member_Master'!J7) | D7: =IF('02_Common_Member_Master'!K7="","",'02_Common_Member_Master'!K7) | E7: =IF('02_Common_Member_Master'!L7="","",'02_Common_Member_Master'!L7) | F7: =IF('02_Common_Member_Master'!M7="","",'02_Common_Member_Master'!M7) | G7: =IF('02_Common_Member_Master'!N7="","",'02_Common_Member_Master'!N7) | H7: =IF('02_Common_Member_Master'!O7="","",'02_Common_Member_Master'!O7) | I7: =IF('02_Common_Member_Master'!P7="","",'02_Common_Member_Master'!P7)
A8: =IF('02_Common_Member_Master'!A8="","",'02_Common_Member_Master'!A8) | B8: =IF('02_Common_Member_Master'!I8="","",'02_Common_Member_Master'!I8) | C8: =IF('02_Common_Member_Master'!J8="","",'02_Common_Member_Master'!J8) | D8: =IF('02_Common_Member_Master'!K8="","",'02_Common_Member_Master'!K8) | E8: =IF('02_Common_Member_Master'!L8="","",'02_Common_Member_Master'!L8) | F8: =IF('02_Common_Member_Master'!M8="","",'02_Common_Member_Master'!M8) | G8: =IF('02_Common_Member_Master'!N8="","",'02_Common_Member_Master'!N8) | H8: =IF('02_Common_Member_Master'!O8="","",'02_Common_Member_Master'!O8) | I8: =IF('02_Common_Member_Master'!P8="","",'02_Common_Member_Master'!P8)
A9: =IF('02_Common_Member_Master'!A9="","",'02_Common_Member_Master'!A9) | B9: =IF('02_Common_Member_Master'!I9="","",'02_Common_Member_Master'!I9) | C9: =IF('02_Common_Member_Master'!J9="","",'02_Common_Member_Master'!J9) | D9: =IF('02_Common_Member_Master'!K9="","",'02_Common_Member_Master'!K9) | E9: =IF('02_Common_Member_Master'!L9="","",'02_Common_Member_Master'!L9) | F9: =IF('02_Common_Member_Master'!M9="","",'02_Common_Member_Master'!M9) | G9: =IF('02_Common_Member_Master'!N9="","",'02_Common_Member_Master'!N9) | H9: =IF('02_Common_Member_Master'!O9="","",'02_Common_Member_Master'!O9) | I9: =IF('02_Common_Member_Master'!P9="","",'02_Common_Member_Master'!P9)
A10: =IF('02_Common_Member_Master'!A10="","",'02_Common_Member_Master'!A10) | B10: =IF('02_Common_Member_Master'!I10="","",'02_Common_Member_Master'!I10) | C10: =IF('02_Common_Member_Master'!J10="","",'02_Common_Member_Master'!J10) | D10: =IF('02_Common_Member_Master'!K10="","",'02_Common_Member_Master'!K10) | E10: =IF('02_Common_Member_Master'!L10="","",'02_Common_Member_Master'!L10) | F10: =IF('02_Common_Member_Master'!M10="","",'02_Common_Member_Master'!M10) | G10: =IF('02_Common_Member_Master'!N10="","",'02_Common_Member_Master'!N10) | H10: =IF('02_Common_Member_Master'!O10="","",'02_Common_Member_Master'!O10) | I10: =IF('02_Common_Member_Master'!P10="","",'02_Common_Member_Master'!P10)
A11: =IF('02_Common_Member_Master'!A11="","",'02_Common_Member_Master'!A11) | B11: =IF('02_Common_Member_Master'!I11="","",'02_Common_Member_Master'!I11) | C11: =IF('02_Common_Member_Master'!J11="","",'02_Common_Member_Master'!J11) | D11: =IF('02_Common_Member_Master'!K11="","",'02_Common_Member_Master'!K11) | E11: =IF('02_Common_Member_Master'!L11="","",'02_Common_Member_Master'!L11) | F11: =IF('02_Common_Member_Master'!M11="","",'02_Common_Member_Master'!M11) | G11: =IF('02_Common_Member_Master'!N11="","",'02_Common_Member_Master'!N11) | H11: =IF('02_Common_Member_Master'!O11="","",'02_Common_Member_Master'!O11) | I11: =IF('02_Common_Member_Master'!P11="","",'02_Common_Member_Master'!P11)
A12: =IF('02_Common_Member_Master'!A12="","",'02_Common_Member_Master'!A12) | B12: =IF('02_Common_Member_Master'!I12="","",'02_Common_Member_Master'!I12) | C12: =IF('02_Common_Member_Master'!J12="","",'02_Common_Member_Master'!J12) | D12: =IF('02_Common_Member_Master'!K12="","",'02_Common_Member_Master'!K12) | E12: =IF('02_Common_Member_Master'!L12="","",'02_Common_Member_Master'!L12) | F12: =IF('02_Common_Member_Master'!M12="","",'02_Common_Member_Master'!M12) | G12: =IF('02_Common_Member_Master'!N12="","",'02_Common_Member_Master'!N12) | H12: =IF('02_Common_Member_Master'!O12="","",'02_Common_Member_Master'!O12) | I12: =IF('02_Common_Member_Master'!P12="","",'02_Common_Member_Master'!P12)
A13: =IF('02_Common_Member_Master'!A13="","",'02_Common_Member_Master'!A13) | B13: =IF('02_Common_Member_Master'!I13="","",'02_Common_Member_Master'!I13) | C13: =IF('02_Common_Member_Master'!J13="","",'02_Common_Member_Master'!J13) | D13: =IF('02_Common_Member_Master'!K13="","",'02_Common_Member_Master'!K13) | E13: =IF('02_Common_Member_Master'!L13="","",'02_Common_Member_Master'!L13) | F13: =IF('02_Common_Member_Master'!M13="","",'02_Common_Member_Master'!M13) | G13: =IF('02_Common_Member_Master'!N13="","",'02_Common_Member_Master'!N13) | H13: =IF('02_Common_Member_Master'!O13="","",'02_Common_Member_Master'!O13) | I13: =IF('02_Common_Member_Master'!P13="","",'02_Common_Member_Master'!P13)
A14: =IF('02_Common_Member_Master'!A14="","",'02_Common_Member_Master'!A14) | B14: =IF('02_Common_Member_Master'!I14="","",'02_Common_Member_Master'!I14) | C14: =IF('02_Common_Member_Master'!J14="","",'02_Common_Member_Master'!J14) | D14: =IF('02_Common_Member_Master'!K14="","",'02_Common_Member_Master'!K14) | E14: =IF('02_Common_Member_Master'!L14="","",'02_Common_Member_Master'!L14) | F14: =IF('02_Common_Member_Master'!M14="","",'02_Common_Member_Master'!M14) | G14: =IF('02_Common_Member_Master'!N14="","",'02_Common_Member_Master'!N14) | H14: =IF('02_Common_Member_Master'!O14="","",'02_Common_Member_Master'!O14) | I14: =IF('02_Common_Member_Master'!P14="","",'02_Common_Member_Master'!P14)
... A23: =IF('02_Common_Member_Master'!A23="","",'02_Common_Member_Master'!A23) | B23: =IF('02_Common_Member_Master'!I23="","",'02_Common_Member_Master'!I23) | C23: =IF('02_Common_Member_Master'!J23="","",'02_Common_Member_Master'!J23) | D23: =IF('02_Common_Member_Master'!K23="","",'02_Common_Member_Master'!K23) | E23: =IF('02_Common_Member_Master'!L23="","",'02_Common_Member_Master'!L23) | F23: =IF('02_Common_Member_Master'!M23="","",'02_Common_Member_Master'!M23) | G23: =IF('02_Common_Member_Master'!N23="","",'02_Common_Member_Master'!N23) | H23: =IF('02_Common_Member_Master'!O23="","",'02_Common_Member_Master'!O23) | I23: =IF('02_Common_Member_Master'!P23="","",'02_Common_Member_Master'!P23)

Sheet 07_Property_Register
A1: Sr. No. | B1: Name of Co-partner Member | H1: Date of Possession | I1: Distinguishing No. of Tenement | K1: Description of Tenement | L1: Area of Tenement | M1: Cost of Tenement | O1: Annual Ground Rent Rs. | P1: Date of Cessation of Membership | Q1: Signature Chairman / Hon. Secretary | R1: Remarks (Reason of Cessation / Transfer to Sr. No. and Date)
B2: 1 | C2: 2 | D2: 3 | E2: 4 | F2: 5 | G2: 6 | I2: Flat No. | J2: Floor No. | M2: Land Rs. | N2: Const. Rs.
A3: =IF('02_Common_Member_Master'!A3="","",'02_Common_Member_Master'!A3) | B3: =IF('02_Common_Member_Master'!I3="","",'02_Common_Member_Master'!I3) | C3: =IF('02_Common_Member_Master'!J3="","",'02_Common_Member_Master'!J3) | D3: =IF('02_Common_Member_Master'!K3="","",'02_Common_Member_Master'!K3) | E3: =IF('02_Common_Member_Master'!L3="","",'02_Common_Member_Master'!L3) | F3: =IF('02_Common_Member_Master'!M3="","",'02_Common_Member_Master'!M3) | G3: =IF('02_Common_Member_Master'!N3="","",'02_Common_Member_Master'!N3) | I3: =IF('02_Common_Member_Master'!O3="","",'02_Common_Member_Master'!O3)
A4: =IF('02_Common_Member_Master'!A4="","",'02_Common_Member_Master'!A4) | B4: =IF('02_Common_Member_Master'!I4="","",'02_Common_Member_Master'!I4) | C4: =IF('02_Common_Member_Master'!J4="","",'02_Common_Member_Master'!J4) | D4: =IF('02_Common_Member_Master'!K4="","",'02_Common_Member_Master'!K4) | E4: =IF('02_Common_Member_Master'!L4="","",'02_Common_Member_Master'!L4) | F4: =IF('02_Common_Member_Master'!M4="","",'02_Common_Member_Master'!M4) | G4: =IF('02_Common_Member_Master'!N4="","",'02_Common_Member_Master'!N4) | I4: =IF('02_Common_Member_Master'!O4="","",'02_Common_Member_Master'!O4)
A5: =IF('02_Common_Member_Master'!A5="","",'02_Common_Member_Master'!A5) | B5: =IF('02_Common_Member_Master'!I5="","",'02_Common_Member_Master'!I5) | C5: =IF('02_Common_Member_Master'!J5="","",'02_Common_Member_Master'!J5) | D5: =IF('02_Common_Member_Master'!K5="","",'02_Common_Member_Master'!K5) | E5: =IF('02_Common_Member_Master'!L5="","",'02_Common_Member_Master'!L5) | F5: =IF('02_Common_Member_Master'!M5="","",'02_Common_Member_Master'!M5) | G5: =IF('02_Common_Member_Master'!N5="","",'02_Common_Member_Master'!N5) | I5: =IF('02_Common_Member_Master'!O5="","",'02_Common_Member_Master'!O5)
A6: =IF('02_Common_Member_Master'!A6="","",'02_Common_Member_Master'!A6) | B6: =IF('02_Common_Member_Master'!I6="","",'02_Common_Member_Master'!I6) | C6: =IF('02_Common_Member_Master'!J6="","",'02_Common_Member_Master'!J6) | D6: =IF('02_Common_Member_Master'!K6="","",'02_Common_Member_Master'!K6) | E6: =IF('02_Common_Member_Master'!L6="","",'02_Common_Member_Master'!L6) | F6: =IF('02_Common_Member_Master'!M6="","",'02_Common_Member_Master'!M6) | G6: =IF('02_Common_Member_Master'!N6="","",'02_Common_Member_Master'!N6) | I6: =IF('02_Common_Member_Master'!O6="","",'02_Common_Member_Master'!O6)
A7: =IF('02_Common_Member_Master'!A7="","",'02_Common_Member_Master'!A7) | B7: =IF('02_Common_Member_Master'!I7="","",'02_Common_Member_Master'!I7) | C7: =IF('02_Common_Member_Master'!J7="","",'02_Common_Member_Master'!J7) | D7: =IF('02_Common_Member_Master'!K7="","",'02_Common_Member_Master'!K7) | E7: =IF('02_Common_Member_Master'!L7="","",'02_Common_Member_Master'!L7) | F7: =IF('02_Common_Member_Master'!M7="","",'02_Common_Member_Master'!M7) | G7: =IF('02_Common_Member_Master'!N7="","",'02_Common_Member_Master'!N7) | I7: =IF('02_Common_Member_Master'!O7="","",'02_Common_Member_Master'!O7)
A8: =IF('02_Common_Member_Master'!A8="","",'02_Common_Member_Master'!A8) | B8: =IF('02_Common_Member_Master'!I8="","",'02_Common_Member_Master'!I8) | C8: =IF('02_Common_Member_Master'!J8="","",'02_Common_Member_Master'!J8) | D8: =IF('02_Common_Member_Master'!K8="","",'02_Common_Member_Master'!K8) | E8: =IF('02_Common_Member_Master'!L8="","",'02_Common_Member_Master'!L8) | F8: =IF('02_Common_Member_Master'!M8="","",'02_Common_Member_Master'!M8) | G8: =IF('02_Common_Member_Master'!N8="","",'02_Common_Member_Master'!N8) | I8: =IF('02_Common_Member_Master'!O8="","",'02_Common_Member_Master'!O8)
A9: =IF('02_Common_Member_Master'!A9="","",'02_Common_Member_Master'!A9) | B9: =IF('02_Common_Member_Master'!I9="","",'02_Common_Member_Master'!I9) | C9: =IF('02_Common_Member_Master'!J9="","",'02_Common_Member_Master'!J9) | D9: =IF('02_Common_Member_Master'!K9="","",'02_Common_Member_Master'!K9) | E9: =IF('02_Common_Member_Master'!L9="","",'02_Common_Member_Master'!L9) | F9: =IF('02_Common_Member_Master'!M9="","",'02_Common_Member_Master'!M9) | G9: =IF('02_Common_Member_Master'!N9="","",'02_Common_Member_Master'!N9) | I9: =IF('02_Common_Member_Master'!O9="","",'02_Common_Member_Master'!O9)
A10: =IF('02_Common_Member_Master'!A10="","",'02_Common_Member_Master'!A10) | B10: =IF('02_Common_Member_Master'!I10="","",'02_Common_Member_Master'!I10) | C10: =IF('02_Common_Member_Master'!J10="","",'02_Common_Member_Master'!J10) | D10: =IF('02_Common_Member_Master'!K10="","",'02_Common_Member_Master'!K10) | E10: =IF('02_Common_Member_Master'!L10="","",'02_Common_Member_Master'!L10) | F10: =IF('02_Common_Member_Master'!M10="","",'02_Common_Member_Master'!M10) | G10: =IF('02_Common_Member_Master'!N10="","",'02_Common_Member_Master'!N10) | I10: =IF('02_Common_Member_Master'!O10="","",'02_Common_Member_Master'!O10)
A11: =IF('02_Common_Member_Master'!A11="","",'02_Common_Member_Master'!A11) | B11: =IF('02_Common_Member_Master'!I11="","",'02_Common_Member_Master'!I11) | C11: =IF('02_Common_Member_Master'!J11="","",'02_Common_Member_Master'!J11) | D11: =IF('02_Common_Member_Master'!K11="","",'02_Common_Member_Master'!K11) | E11: =IF('02_Common_Member_Master'!L11="","",'02_Common_Member_Master'!L11) | F11: =IF('02_Common_Member_Master'!M11="","",'02_Common_Member_Master'!M11) | G11: =IF('02_Common_Member_Master'!N11="","",'02_Common_Member_Master'!N11) | I11: =IF('02_Common_Member_Master'!O11="","",'02_Common_Member_Master'!O11)
A12: =IF('02_Common_Member_Master'!A12="","",'02_Common_Member_Master'!A12) | B12: =IF('02_Common_Member_Master'!I12="","",'02_Common_Member_Master'!I12) | C12: =IF('02_Common_Member_Master'!J12="","",'02_Common_Member_Master'!J12) | D12: =IF('02_Common_Member_Master'!K12="","",'02_Common_Member_Master'!K12) | E12: =IF('02_Common_Member_Master'!L12="","",'02_Common_Member_Master'!L12) | F12: =IF('02_Common_Member_Master'!M12="","",'02_Common_Member_Master'!M12) | G12: =IF('02_Common_Member_Master'!N12="","",'02_Common_Member_Master'!N12) | I12: =IF('02_Common_Member_Master'!O12="","",'02_Common_Member_Master'!O12)
A13: =IF('02_Common_Member_Master'!A13="","",'02_Common_Member_Master'!A13) | B13: =IF('02_Common_Member_Master'!I13="","",'02_Common_Member_Master'!I13) | C13: =IF('02_Common_Member_Master'!J13="","",'02_Common_Member_Master'!J13) | D13: =IF('02_Common_Member_Master'!K13="","",'02_Common_Member_Master'!K13) | E13: =IF('02_Common_Member_Master'!L13="","",'02_Common_Member_Master'!L13) | F13: =IF('02_Common_Member_Master'!M13="","",'02_Common_Member_Master'!M13) | G13: =IF('02_Common_Member_Master'!N13="","",'02_Common_Member_Master'!N13) | I13: =IF('02_Common_Member_Master'!O13="","",'02_Common_Member_Master'!O13)
A14: =IF('02_Common_Member_Master'!A14="","",'02_Common_Member_Master'!A14) | B14: =IF('02_Common_Member_Master'!I14="","",'02_Common_Member_Master'!I14) | C14: =IF('02_Common_Member_Master'!J14="","",'02_Common_Member_Master'!J14) | D14: =IF('02_Common_Member_Master'!K14="","",'02_Common_Member_Master'!K14) | E14: =IF('02_Common_Member_Master'!L14="","",'02_Common_Member_Master'!L14) | F14: =IF('02_Common_Member_Master'!M14="","",'02_Common_Member_Master'!M14) | G14: =IF('02_Common_Member_Master'!N14="","",'02_Common_Member_Master'!N14) | I14: =IF('02_Common_Member_Master'!O14="","",'02_Common_Member_Master'!O14)
... A23: =IF('02_Common_Member_Master'!A23="","",'02_Common_Member_Master'!A23) | B23: =IF('02_Common_Member_Master'!I23="","",'02_Common_Member_Master'!I23) | C23: =IF('02_Common_Member_Master'!J23="","",'02_Common_Member_Master'!J23) | D23: =IF('02_Common_Member_Master'!K23="","",'02_Common_Member_Master'!K23) | E23: =IF('02_Common_Member_Master'!L23="","",'02_Common_Member_Master'!L23) | F23: =IF('02_Common_Member_Master'!M23="","",'02_Common_Member_Master'!M23) | G23: =IF('02_Common_Member_Master'!N23="","",'02_Common_Member_Master'!N23) | I23: =IF('02_Common_Member_Master'!O23="","",'02_Common_Member_Master'!O23)

Sheet 08_Lien_Mark_Register
A1: Sr. No. | B1: Wing / Flat No. | D1: Members Name | J1: Flat Area | K1: Type of Membership | L1: Remarks | M1: PARTICULARS OF LOAN - 1st LOAN | V1: PARTICULARS OF LOAN - 2nd LOAN OR LOAN TOP-UP | AE1: PARTICULARS OF LOAN - 3rd LOAN OR LOAN TOP-UP | AN1: PARTICULARS OF LOAN - 4th LOAN OR LOAN TOP-UP
B2: Wing No. | C2: Flat No. | D2: 1 | E2: 2 | F2: 3 | G2: 4 | H2: 5 | I2: 6 | M2: Name of the Bank | N2: Bank Address | O2: Loan Amount | P2: Period of Loan | Q2: Managing Committee Meeting Date | R2: Resolution No. | S2: Date of NOC given by Society | T2: Date of Documents of Lien Cancellation | U2: Remarks | V2: Name of the Bank | W2: Bank Address | X2: Loan Amount | Y2: Period of Loan | Z2: Managing Committee Meeting Date | AA2: Resolution No. | AB2: Date of NOC given by Society | AC2: Date of Documents of Lien Cancellation | AD2: Remarks | AE2: Name of the Bank | AF2: Bank Address | AG2: Loan Amount | AH2: Period of Loan | AI2: Managing Committee Meeting Date | AJ2: Resolution No. | AK2: Date of NOC given by Society | AL2: Date of Documents of Lien Cancellation | AM2: Remarks | AN2: Name of the Bank | AO2: Bank Address | AP2: Loan Amount | AQ2: Period of Loan | AR2: Managing Committee Meeting Date | AS2: Resolution No. | AT2: Date of NOC given by Society | AU2: Date of Documents of Lien Cancellation | AV2: Remarks
A3: =IF('02_Common_Member_Master'!A3="","",'02_Common_Member_Master'!A3) | B3: =IF('02_Common_Member_Master'!P3="","",'02_Common_Member_Master'!P3) | C3: =IF('02_Common_Member_Master'!O3="","",'02_Common_Member_Master'!O3) | D3: =IF('02_Common_Member_Master'!I3="","",'02_Common_Member_Master'!I3) | E3: =IF('02_Common_Member_Master'!J3="","",'02_Common_Member_Master'!J3) | F3: =IF('02_Common_Member_Master'!K3="","",'02_Common_Member_Master'!K3) | G3: =IF('02_Common_Member_Master'!L3="","",'02_Common_Member_Master'!L3) | H3: =IF('02_Common_Member_Master'!M3="","",'02_Common_Member_Master'!M3) | I3: =IF('02_Common_Member_Master'!N3="","",'02_Common_Member_Master'!N3)
A4: =IF('02_Common_Member_Master'!A4="","",'02_Common_Member_Master'!A4) | B4: =IF('02_Common_Member_Master'!P4="","",'02_Common_Member_Master'!P4) | C4: =IF('02_Common_Member_Master'!O4="","",'02_Common_Member_Master'!O4) | D4: =IF('02_Common_Member_Master'!I4="","",'02_Common_Member_Master'!I4) | E4: =IF('02_Common_Member_Master'!J4="","",'02_Common_Member_Master'!J4) | F4: =IF('02_Common_Member_Master'!K4="","",'02_Common_Member_Master'!K4) | G4: =IF('02_Common_Member_Master'!L4="","",'02_Common_Member_Master'!L4) | H4: =IF('02_Common_Member_Master'!M4="","",'02_Common_Member_Master'!M4) | I4: =IF('02_Common_Member_Master'!N4="","",'02_Common_Member_Master'!N4)
A5: =IF('02_Common_Member_Master'!A5="","",'02_Common_Member_Master'!A5) | B5: =IF('02_Common_Member_Master'!P5="","",'02_Common_Member_Master'!P5) | C5: =IF('02_Common_Member_Master'!O5="","",'02_Common_Member_Master'!O5) | D5: =IF('02_Common_Member_Master'!I5="","",'02_Common_Member_Master'!I5) | E5: =IF('02_Common_Member_Master'!J5="","",'02_Common_Member_Master'!J5) | F5: =IF('02_Common_Member_Master'!K5="","",'02_Common_Member_Master'!K5) | G5: =IF('02_Common_Member_Master'!L5="","",'02_Common_Member_Master'!L5) | H5: =IF('02_Common_Member_Master'!M5="","",'02_Common_Member_Master'!M5) | I5: =IF('02_Common_Member_Master'!N5="","",'02_Common_Member_Master'!N5)
